Workbook

Sheet 📋 Panduan
B2: 📋 JURNAL TRADING — PANDUAN PAKAI
B4: ① IMPORT KE GOOGLE SHEETS
B5: sheets.google.com → File → Import → Upload → pilih "Create new spreadsheet".
B6: Lalu set File → Settings → Locale ke Indonesia (biar tanggal dd/mm terbaca benar).
B7: File ini dioptimalkan untuk Google Sheets. Di Excel, SPARKLINE/IMAGE/REGEXEXTRACT error #NAME?.
B9: ② PASANG GRAFIK (sekali saja, ~2 menit)
B10: Grafik native tidak bisa ikut lewat file .xlsx, jadi dipasang lewat skrip kecil:
B11: 1. Extensions → Apps Script
B12: 2. Hapus isi editor, paste seluruh isi file journal-charts.gs
B13: 3. Simpan (💾) → pilih fungsi buatGrafik → Run → Authorize akses
B14: 4. Balik ke tab 📊 Dashboard — 6 grafik sudah terpasang
B15: Grafik update otomatis tiap kamu isi trade. Jalankan ulang buatGrafik kalau mau reset posisi.
... B45: PETUNJUK ARAH. Kumpulkan 3–6 bulan sebelum membuang satu jenis setup.

Sheet ⚙️ Setelan
A1: ⚙️ SETELAN — isi sekali di awal bulan
A3: Modal Awal (USD) | B3: 1000 | C3: ← ubah angka di kolom hijau sesuai akunmu
A4: Risiko per Trade (%) | B4: 1
A5: Batas Rugi Harian (USD) | B5: 30
A6: Max Trade per Malam | B6: 5
A7: Target Profit Bulanan (USD) | B7: 1000
A8: Kurs USD → IDR | B8: 16000
A9: Jeda Min Setelah Loss (menit) | B9: 10
A11: SPESIFIKASI INSTRUMEN
A12: Dipakai rumus PnL. Rentang VLOOKUP sampai baris 20 — ada 2 baris kosong untuk instrumen tambahan.
A13: Instrumen | B13: Ukuran Kontrak | C13: Pembagi Konversi | D13: Nilai per 1.00 Gerak/Lot (USD) | E13: Biaya per Lot (USD) | F13: Digit
A14: XAUUSD | B14: 100 | C14: 1 | D14: =B14/C14 | E14: 11 | F14: 2
A15: BTCUSD | B15: 1 | C15: 1 | D15: =B15/C15 | E15: 8.75 | F15: 2
A16: EURUSD | B16: 100000 | C16: 1 | D16: =B16/C16 | E16: 10 | F16: 5
A17: GBPUSD | B17: 100000 | C17: 1 | D17: =B17/C17 | E17: 15 | F17: 5
A18: USDJPY | B18: 100000 | C18: 155 | D18: =B18/C18 | E18: 6.5 | F18: 3
A19: Biaya per Lot = komisi round-turn per 1.0 lot. XAU $11 & BTC $8.75 diambil dari CSV brokermu 31 Agu 2026.
A20: Angka ini komisi saja. Kalau akunmu spread-based (bukan raw), tambahkan estimasi spread ke sini.

Sheet 📒 Jurnal
A1: IDENTITAS | H1: SETUP & KONTEKS | N1: HARGA & UKURAN | T1: HITUNGAN OTOMATIS | AB1: MAE / MFE | AF1: PSIKOLOGI & EKSEKUSI | AL1: DETEKSI | AM1: BUKTI | AQ1: BANTU
A2: No | B2: Tanggal | C2: Jam Masuk | D2: Jam Keluar | E2: Sesi | F2: Instrumen | G2: Arah | H2: Tipe Setup | I2: TF Eksekusi | J2: Bias M15 Searah? | K2: Bias EMA200 Searah? | L2: Konfluensi SVP | M2: News Besar? | N2: Entry | O2: Stop Loss | P2: TP Rencana | Q2: Exit Aktual | R2: Lot Saran | S2: Lot Dipakai | T2: Risiko $ | U2: RR Rencana | V2: PnL Kotor $ | W2: Biaya $ | X2: PnL Bersih $ | Y2: R Hasil | Z2: Hasil | AA2: Durasi (mnt) | AB2: Harga Terburuk | AC2: Harga Terbaik | AD2: MAE (R) | AE2: MFE (R) | AF2: Emosi Sebelum Entry | AG2: Kondisi Fisik | AH2: Keyakinan (1-5) | AI2: Sesuai Checklist? | AJ2: Kesalahan | AK2: Catatan | AL2: ⚠️ Cek Revenge | AM2: Link Sebelum | AN2: Gambar Sebelum | AO2: Link Sesudah | AP2: Gambar Sesudah | AQ2: Lolos Filter
A3: =IF($B3="","",ROW()-2) | B3: 46265 | C3: 0.33241898 | D3: 0.33302083 | E3: =IF($C3="","",IF(AND($C3>=TIME(14,0,0),$C3<TIME(19,30,0)),"London",IF(AND($C3>=TIME(19,30,0),$C3<TIME(23,0,0)),"Overlap LDN+NY",IF(OR($C3>=TIME(23,0,0),$C3<TIME(4,0,0)),"New York","Asia")))) | F3: BTCUSD | G3: Sell | N3: 77918.24 | Q3: 77927.4 | R3: =IFERROR(IF(OR($N3="",$O3="",$F3=""),"",ROUND(('⚙️ Setelan'!$B$3*'⚙️ Setelan'!$B$4/100)/(ABS($N3-$O3)*VLOOKUP($F3,'⚙️ Setelan'!$A$14:$F$20,4,FALSE)),2)),"") | S3: 0.1 | T3: =IFERROR(IF(OR($N3="",$O3="",$S3=""),"",ABS($N3-$O3)*$S3*VLOOKUP($F3,'⚙️ Setelan'!$A$14:$F$20,4,FALSE)),"") | U3: =IFERROR(IF(OR($N3="",$O3="",$P3=""),"",ROUND(ABS($P3-$N3)/ABS($N3-$O3),2)),"") | V3: =IFERROR(IF(OR($Q3="",$N3="",$S3=""),"",($Q3-$N3)*IF($G3="Buy",1,-1)*$S3*VLOOKUP($F3,'⚙️ Setelan'!$A$14:$F$20,4,FALSE)),"") | W3: =IFERROR(IF(OR($S3="",$F3=""),"",$S3*VLOOKUP($F3,'⚙️ Setelan'!$A$14:$F$20,5,FALSE)),"") | X3: =IF($V3="","",$V3-IF($W3="",0,$W3)) | Y3: =IF(OR($X3="",$T3="",$T3=0),"",ROUND($X3/$T3,2)) | Z3: =IF($X3="","",IF($X3>0,"Win",IF($X3<0,"Loss","BE"))) | AA3: =IF(OR($C3="",$D3=""),"",ROUND(MOD($D3-$C3,1)*1440,0)) | AD3: =IFERROR(IF(OR($AB3="",$T3="",$T3=0),"",ROUND(ABS($N3-$AB3)*$S3*VLOOKUP($F3,'⚙️ Setelan'!$A$14:$F$20,4,FALSE)/$T3,2)),"") | AE3: =IFERROR(IF(OR($AC3="",$T3="",$T3=0),"",ROUND(ABS($AC3-$N3)*$S3*VLOOKUP($F3,'⚙️ Setelan'!$A$14:$F$20,4,FALSE)/$T3,2)),"") | AK3: tiket 2313145589 · impor CSV · ⚠️ TANPA SL di broker — isi SL yang kamu niatkan biar Risiko $ dan R Hasil bisa terhitung | AL3: ="" | AN3: =IF($AM3="","",IFERROR(IMAGE(IF(REGEXMATCH($AM3,"\.(png|jpg|jpeg|gif)$"),$AM3,"https://s3.tradingview.com/snapshots/"&LOWER(MID(REGEXEXTRACT($AM3,"/x/([A-Za-z0-9]+)"),1,1))&"/"&REGEXEXTRACT($AM3,"/x/([A-Za-z0-9]+)")&".png"),1),"⚠️ link tidak dikenali")) | AP3: =IF($AO3="","",IFERROR(IMAGE(IF(REGEXMATCH($AO3,"\.(png|jpg|jpeg|gif)$"),$AO3,"https://s3.tradingview.com/snapshots/"&LOWER(MID(REGEXEXTRACT($AO3,"/x/([A-Za-z0-9]+)"),1,1))&"/"&REGEXEXTRACT($AO3,"/x/([A-Za-z0-9]+)")&".png"),1),"⚠️ link tidak dikenali")) | AQ3: =IF($Z3="",0,IF(AND(OR('📊 Dashboard'!$B$4="(Semua)",$F3='📊 Dashboard'!$B$4),OR('📊 Dashboard'!$B$5="(Semua)",$H3='📊 Dashboard'!$B$5),OR('📊 Dashboard'!$B$6="(Semua)",$E3='📊 Dashboard'!$B$6),OR('📊 Dashboard'!$B$7="(Semua)",$AF3='📊 Dashboard'!$B$7),OR('📊 Dashboard'!$B$8="(Semua)",$AG3='📊 Dashboard'!$B$8),OR('📊 Dashboard'!$B$9="(Semua)",$K3='📊 Dashboard'!$B$9)),1,0))
A4: =IF($B4="","",ROW()-2) | B4: 46265 | C4: 0.33244213 | D4: 0.33302083 | E4: =IF($C4="","",IF(AND($C4>=TIME(14,0,0),$C4<TIME(19,30,0)),"London",IF(AND($C4>=TIME(19,30,0),$C4<TIME(23,0,0)),"Overlap LDN+NY",IF(OR($C4>=TIME(23,0,0),$C4<TIME(4,0,0)),"New York","Asia")))) | F4: BTCUSD | G4: Sell | N4: 77919.68 | Q4: 77927.4 | R4: =IFERROR(IF(OR($N4="",$O4="",$F4=""),"",ROUND(('⚙️ Setelan'!$B$3*'⚙️ Setelan'!$B$4/100)/(ABS($N4-$O4)*VLOOKUP($F4,'⚙️ Setelan'!$A$14:$F$20,4,FALSE)),2)),"") | S4: 0.1 | T4: =IFERROR(IF(OR($N4="",$O4="",$S4=""),"",ABS($N4-$O4)*$S4*VLOOKUP($F4,'⚙️ Setelan'!$A$14:$F$20,4,FALSE)),"") | U4: =IFERROR(IF(OR($N4="",$O4="",$P4=""),"",ROUND(ABS($P4-$N4)/ABS($N4-$O4),2)),"") | V4: =IFERROR(IF(OR($Q4="",$N4="",$S4=""),"",($Q4-$N4)*IF($G4="Buy",1,-1)*$S4*VLOOKUP($F4,'⚙️ Setelan'!$A$14:$F$20,4,FALSE)),"") | W4: =IFERROR(IF(OR($S4="",$F4=""),"",$S4*VLOOKUP($F4,'⚙️ Setelan'!$A$14:$F$20,5,FALSE)),"") | X4: =IF($V4="","",$V4-IF($W4="",0,$W4)) | Y4: =IF(OR($X4="",$T4="",$T4=0),"",ROUND($X4/$T4,2)) | Z4: =IF($X4="","",IF($X4>0,"Win",IF($X4<0,"Loss","BE"))) | AA4: =IF(OR($C4="",$D4=""),"",ROUND(MOD($D4-$C4,1)*1440,0)) | AD4: =IFERROR(IF(OR($AB4="",$T4="",$T4=0),"",ROUND(ABS($N4-$AB4)*$S4*VLOOKUP($F4,'⚙️ Setelan'!$A$14:$F$20,4,FALSE)/$T4,2)),"") | AE4: =IFERROR(IF(OR($AC4="",$T4="",$T4=0),"",ROUND(ABS($AC4-$N4)*$S4*VLOOKUP($F4,'⚙️ Setelan'!$A$14:$F$20,4,FALSE)/$T4,2)),"") | AK4: tiket 2313145614 · impor CSV · ⚠️ TANPA SL di broker — isi SL yang kamu niatkan biar Risiko $ dan R Hasil bisa terhitung | AL4: =IF(OR($C4="",$B4=""),"",IF(AND($Z3="Loss",$B4=$B3,MOD($C4-$D3,1)*1440<'⚙️ Setelan'!$B$9),"⚠️ Revenge","")) | AN4: =IF($AM4="","",IFERROR(IMAGE(IF(REGEXMATCH($AM4,"\.(png|jpg|jpeg|gif)$"),$AM4,"https://s3.tradingview.com/snapshots/"&LOWER(MID(REGEXEXTRACT($AM4,"/x/([A-Za-z0-9]+)"),1,1))&"/"&REGEXEXTRACT($AM4,"/x/([A-Za-z0-9]+)")&".png"),1),"⚠️ link tidak dikenali")) | AP4: =IF($AO4="","",IFERROR(IMAGE(IF(REGEXMATCH($AO4,"\.(png|jpg|jpeg|gif)$"),$AO4,"https://s3.tradingview.com/snapshots/"&LOWER(MID(REGEXEXTRACT($AO4,"/x/([A-Za-z0-9]+)"),1,1))&"/"&REGEXEXTRACT($AO4,"/x/([A-Za-z0-9]+)")&".png"),1),"⚠️ link tidak dikenali")) | AQ4: =IF($Z4="",0,IF(AND(OR('📊 Dashboard'!$B$4="(Semua)",$F4='📊 Dashboard'!$B$4),OR('📊 Dashboard'!$B$5="(Semua)",$H4='📊 Dashboard'!$B$5),OR('📊 Dashboard'!$B$6="(Semua)",$E4='📊 Dashboard'!$B$6),OR('📊 Dashboard'!$B$7="(Semua)",$AF4='📊 Dashboard'!$B$7),OR('📊 Dashboard'!$B$8="(Semua)",$AG4='📊 Dashboard'!$B$8),OR('📊 Dashboard'!$B$9="(Semua)",$K4='📊 Dashboard'!$B$9)),1,0))
A5: =IF($B5="","",ROW()-2) | B5: 46265 | C5: 0.33340278 | D5: 0.33368056 | E5: =IF($C5="","",IF(AND($C5>=TIME(14,0,0),$C5<TIME(19,30,0)),"London",IF(AND($C5>=TIME(19,30,0),$C5<TIME(23,0,0)),"Overlap LDN+NY",IF(OR($C5>=TIME(23,0,0),$C5<TIME(4,0,0)),"New York","Asia")))) | F5: XAUUSD | G5: Sell | N5: 4453.46 | Q5: 4448.468 | R5: =IFERROR(IF(OR($N5="",$O5="",$F5=""),"",ROUND(('⚙️ Setelan'!$B$3*'⚙️ Setelan'!$B$4/100)/(ABS($N5-$O5)*VLOOKUP($F5,'⚙️ Setelan'!$A$14:$F$20,4,FALSE)),2)),"") | S5: 0.09 | T5: =IFERROR(IF(OR($N5="",$O5="",$S5=""),"",ABS($N5-$O5)*$S5*VLOOKUP($F5,'⚙️ Setelan'!$A$14:$F$20,4,FALSE)),"") | U5: =IFERROR(IF(OR($N5="",$O5="",$P5=""),"",ROUND(ABS($P5-$N5)/ABS($N5-$O5),2)),"") | V5: =IFERROR(IF(OR($Q5="",$N5="",$S5=""),"",($Q5-$N5)*IF($G5="Buy",1,-1)*$S5*VLOOKUP($F5,'⚙️ Setelan'!$A$14:$F$20,4,FALSE)),"") | W5: =IFERROR(IF(OR($S5="",$F5=""),"",$S5*VLOOKUP($F5,'⚙️ Setelan'!$A$14:$F$20,5,FALSE)),"") | X5: =IF($V5="","",$V5-IF($W5="",0,$W5)) | Y5: =IF(OR($X5="",$T5="",$T5=0),"",ROUND($X5/$T5,2)) | Z5: =IF($X5="","",IF($X5>0,"Win",IF($X5<0,"Loss","BE"))) | AA5: =IF(OR($C5="",$D5=""),"",ROUND(MOD($D5-$C5,1)*1440,0)) | AD5: =IFERROR(IF(OR($AB5="",$T5="",$T5=0),"",ROUND(ABS($N5-$AB5)*$S5*VLOOKUP($F5,'⚙️ Setelan'!$A$14:$F$20,4,FALSE)/$T5,2)),"") | AE5: =IFERROR(IF(OR($AC5="",$T5="",$T5=0),"",ROUND(ABS($AC5-$N5)*$S5*VLOOKUP($F5,'⚙️ Setelan'!$A$14:$F$20,4,FALSE)/$T5,2)),"") | AK5: tiket 2313151523 · impor CSV · ⚠️ TANPA SL di broker — isi SL yang kamu niatkan biar Risiko $ dan R Hasil bisa terhitung | AL5: =IF(OR($C5="",$B5=""),"",IF(AND($Z4="Loss",$B5=$B4,MOD($C5-$D4,1)*1440<'⚙️ Setelan'!$B$9),"⚠️ Revenge","")) | AN5: =IF($AM5="","",IFERROR(IMAGE(IF(REGEXMATCH($AM5,"\.(png|jpg|jpeg|gif)$"),$AM5,"https://s3.tradingview.com/snapshots/"&LOWER(MID(REGEXEXTRACT($AM5,"/x/([A-Za-z0-9]+)"),1,1))&"/"&REGEXEXTRACT($AM5,"/x/([A-Za-z0-9]+)")&".png"),1),"⚠️ link tidak dikenali")) | AP5: =IF($AO5="","",IFERROR(IMAGE(IF(REGEXMATCH($AO5,"\.(png|jpg|jpeg|gif)$"),$AO5,"https://s3.tradingview.com/snapshots/"&LOWER(MID(REGEXEXTRACT($AO5,"/x/([A-Za-z0-9]+)"),1,1))&"/"&REGEXEXTRACT($AO5,"/x/([A-Za-z0-9]+)")&".png"),1),"⚠️ link tidak dikenali")) | AQ5: =IF($Z5="",0,IF(AND(OR('📊 Dashboard'!$B$4="(Semua)",$F5='📊 Dashboard'!$B$4),OR('📊 Dashboard'!$B$5="(Semua)",$H5='📊 Dashboard'!$B$5),OR('📊 Dashboard'!$B$6="(Semua)",$E5='📊 Dashboard'!$B$6),OR('📊 Dashboard'!$B$7="(Semua)",$AF5='📊 Dashboard'!$B$7),OR('📊 Dashboard'!$B$8="(Semua)",$AG5='📊 Dashboard'!$B$8),OR('📊 Dashboard'!$B$9="(Semua)",$K5='📊 Dashboard'!$B$9)),1,0))
A6: =IF($B6="","",ROW()-2) | B6: 46265 | C6: 0.33340278 | D6: 0.33368056 | E6: =IF($C6="","",IF(AND($C6>=TIME(14,0,0),$C6<TIME(19,30,0)),"London",IF(AND($C6>=TIME(19,30,0),$C6<TIME(23,0,0)),"Overlap LDN+NY",IF(OR($C6>=TIME(23,0,0),$C6<TIME(4,0,0)),"New York","Asia")))) | F6: XAUUSD | G6: Sell | N6: 4453.46 | Q6: 4448.468 | R6: =IFERROR(IF(OR($N6="",$O6="",$F6=""),"",ROUND(('⚙️ Setelan'!$B$3*'⚙️ Setelan'!$B$4/100)/(ABS($N6-$O6)*VLOOKUP($F6,'⚙️ Setelan'!$A$14:$F$20,4,FALSE)),2)),"") | S6: 0.09 | T6: =IFERROR(IF(OR($N6="",$O6="",$S6=""),"",ABS($N6-$O6)*$S6*VLOOKUP($F6,'⚙️ Setelan'!$A$14:$F$20,4,FALSE)),"") | U6: =IFERROR(IF(OR($N6="",$O6="",$P6=""),"",ROUND(ABS($P6-$N6)/ABS($N6-$O6),2)),"") | V6: =IFERROR(IF(OR($Q6="",$N6="",$S6=""),"",($Q6-$N6)*IF($G6="Buy",1,-1)*$S6*VLOOKUP($F6,'⚙️ Setelan'!$A$14:$F$20,4,FALSE)),"") | W6: =IFERROR(IF(OR($S6="",$F6=""),"",$S6*VLOOKUP($F6,'⚙️ Setelan'!$A$14:$F$20,5,FALSE)),"") | X6: =IF($V6="","",$V6-IF($W6="",0,$W6)) | Y6: =IF(OR($X6="",$T6="",$T6=0),"",ROUND($X6/$T6,2)) | Z6: =IF($X6="","",IF($X6>0,"Win",IF($X6<0,"Loss","BE"))) | AA6: =IF(OR($C6="",$D6=""),"",ROUND(MOD($D6-$C6,1)*1440,0)) | AD6: =IFERROR(IF(OR($AB6="",$T6="",$T6=0),"",ROUND(ABS($N6-$AB6)*$S6*VLOOKUP($F6,'⚙️ Setelan'!$A$14:$F$20,4,FALSE)/$T6,2)),"") | AE6: =IFERROR(IF(OR($AC6="",$T6="",$T6=0),"",ROUND(ABS($AC6-$N6)*$S6*VLOOKUP($F6,'⚙️ Setelan'!$A$14:$F$20,4,FALSE)/$T6,2)),"") | AK6: tiket 2313151522 · impor CSV · ⚠️ TANPA SL di broker — isi SL yang kamu niatkan biar Risiko $ dan R Hasil bisa terhitung | AL6: =IF(OR($C6="",$B6=""),"",IF(AND($Z5="Loss",$B6=$B5,MOD($C6-$D5,1)*1440<'⚙️ Setelan'!$B$9),"⚠️ Revenge","")) | AN6: =IF($AM6="","",IFERROR(IMAGE(IF(REGEXMATCH($AM6,"\.(png|jpg|jpeg|gif)$"),$AM6,"https://s3.tradingview.com/snapshots/"&LOWER(MID(REGEXEXTRACT($AM6,"/x/([A-Za-z0-9]+)"),1,1))&"/"&REGEXEXTRACT($AM6,"/x/([A-Za-z0-9]+)")&".png"),1),"⚠️ link tidak dikenali")) | AP6: =IF($AO6="","",IFERROR(IMAGE(IF(REGEXMATCH($AO6,"\.(png|jpg|jpeg|gif)$"),$AO6,"https://s3.tradingview.com/snapshots/"&LOWER(MID(REGEXEXTRACT($AO6,"/x/([A-Za-z0-9]+)"),1,1))&"/"&REGEXEXTRACT($AO6,"/x/([A-Za-z0-9]+)")&".png"),1),"⚠️ link tidak dikenali")) | AQ6: =IF($Z6="",0,IF(AND(OR('📊 Dashboard'!$B$4="(Semua)",$F6='📊 Dashboard'!$B$4),OR('📊 Dashboard'!$B$5="(Semua)",$H6='📊 Dashboard'!$B$5),OR('📊 Dashboard'!$B$6="(Semua)",$E6='📊 Dashboard'!$B$6),OR('📊 Dashboard'!$B$7="(Semua)",$AF6='📊 Dashboard'!$B$7),OR('📊 Dashboard'!$B$8="(Semua)",$AG6='📊 Dashboard'!$B$8),OR('📊 Dashboard'!$B$9="(Semua)",$K6='📊 Dashboard'!$B$9)),1,0))
A7: =IF($B7="","",ROW()-2) | B7: 46265 | C7: 0.37178241 | D7: 0.37438657 | E7: =IF($C7="","",IF(AND($C7>=TIME(14,0,0),$C7<TIME(19,30,0)),"London",IF(AND($C7>=TIME(19,30,0),$C7<TIME(23,0,0)),"Overlap LDN+NY",IF(OR($C7>=TIME(23,0,0),$C7<TIME(4,0,0)),"New York","Asia")))) | F7: XAUUSD | G7: Sell | N7: 4442.994 | Q7: 4440.126 | R7: =IFERROR(IF(OR($N7="",$O7="",$F7=""),"",ROUND(('⚙️ Setelan'!$B$3*'⚙️ Setelan'!$B$4/100)/(ABS($N7-$O7)*VLOOKUP($F7,'⚙️ Setelan'!$A$14:$F$20,4,FALSE)),2)),"") | S7: 0.09 | T7: =IFERROR(IF(OR($N7="",$O7="",$S7=""),"",ABS($N7-$O7)*$S7*VLOOKUP($F7,'⚙️ Setelan'!$A$14:$F$20,4,FALSE)),"") | U7: =IFERROR(IF(OR($N7="",$O7="",$P7=""),"",ROUND(ABS($P7-$N7)/ABS($N7-$O7),2)),"") | V7: =IFERROR(IF(OR($Q7="",$N7="",$S7=""),"",($Q7-$N7)*IF($G7="Buy",1,-1)*$S7*VLOOKUP($F7,'⚙️ Setelan'!$A$14:$F$20,4,FALSE)),"") | W7: =IFERROR(IF(OR($S7="",$F7=""),"",$S7*VLOOKUP($F7,'⚙️ Setelan'!$A$14:$F$20,5,FALSE)),"") | X7: =IF($V7="","",$V7-IF($W7="",0,$W7)) | Y7: =IF(OR($X7="",$T7="",$T7=0),"",ROUND($X7/$T7,2)) | Z7: =IF($X7="","",IF($X7>0,"Win",IF($X7<0,"Loss","BE"))) | AA7: =IF(OR($C7="",$D7=""),"",ROUND(MOD($D7-$C7,1)*1440,0)) | AD7: =IFERROR(IF(OR($AB7="",$T7="",$T7=0),"",ROUND(ABS($N7-$AB7)*$S7*VLOOKUP($F7,'⚙️ Setelan'!$A$14:$F$20,4,FALSE)/$T7,2)),"") | AE7: =IFERROR(IF(OR($AC7="",$T7="",$T7=0),"",ROUND(ABS($AC7-$N7)*$S7*VLOOKUP($F7,'⚙️ Setelan'!$A$14:$F$20,4,FALSE)/$T7,2)),"") | AK7: tiket 2313313924 · impor CSV · ⚠️ TANPA SL di broker — isi SL yang kamu niatkan biar Risiko $ dan R Hasil bisa terhitung | AL7: =IF(OR($C7="",$B7=""),"",IF(AND($Z6="Loss",$B7=$B6,MOD($C7-$D6,1)*1440<'⚙️ Setelan'!$B$9),"⚠️ Revenge","")) | AN7: =IF($AM7="","",IFERROR(IMAGE(IF(REGEXMATCH($AM7,"\.(png|jpg|jpeg|gif)$"),$AM7,"https://s3.tradingview.com/snapshots/"&LOWER(MID(REGEXEXTRACT($AM7,"/x/([A-Za-z0-9]+)"),1,1))&"/"&REGEXEXTRACT($AM7,"/x/([A-Za-z0-9]+)")&".png"),1),"⚠️ link tidak dikenali")) | AP7: =IF($AO7="","",IFERROR(IMAGE(IF(REGEXMATCH($AO7,"\.(png|jpg|jpeg|gif)$"),$AO7,"https://s3.tradingview.com/snapshots/"&LOWER(MID(REGEXEXTRACT($AO7,"/x/([A-Za-z0-9]+)"),1,1))&"/"&REGEXEXTRACT($AO7,"/x/([A-Za-z0-9]+)")&".png"),1),"⚠️ link tidak dikenali")) | AQ7: =IF($Z7="",0,IF(AND(OR('📊 Dashboard'!$B$4="(Semua)",$F7='📊 Dashboard'!$B$4),OR('📊 Dashboard'!$B$5="(Semua)",$H7='📊 Dashboard'!$B$5),OR('📊 Dashboard'!$B$6="(Semua)",$E7='📊 Dashboard'!$B$6),OR('📊 Dashboard'!$B$7="(Semua)",$AF7='📊 Dashboard'!$B$7),OR('📊 Dashboard'!$B$8="(Semua)",$AG7='📊 Dashboard'!$B$8),OR('📊 Dashboard'!$B$9="(Semua)",$K7='📊 Dashboard'!$B$9)),1,0))
A8: =IF($B8="","",ROW()-2) | B8: 46265 | C8: 0.37178241 | D8: 0.37438657 | E8: =IF($C8="","",IF(AND($C8>=TIME(14,0,0),$C8<TIME(19,30,0)),"London",IF(AND($C8>=TIME(19,30,0),$C8<TIME(23,0,0)),"Overlap LDN+NY",IF(OR($C8>=TIME(23,0,0),$C8<TIME(4,0,0)),"New York","Asia")))) | F8: XAUUSD | G8: Sell | N8: 4442.994 | Q8: 4440.261 | R8: =IFERROR(IF(OR($N8="",$O8="",$F8=""),"",ROUND(('⚙️ Setelan'!$B$3*'⚙️ Setelan'!$B$4/100)/(ABS($N8-$O8)*VLOOKUP($F8,'⚙️ Setelan'!$A$14:$F$20,4,FALSE)),2)),"") | S8: 0.09 | T8: =IFERROR(IF(OR($N8="",$O8="",$S8=""),"",ABS($N8-$O8)*$S8*VLOOKUP($F8,'⚙️ Setelan'!$A$14:$F$20,4,FALSE)),"") | U8: =IFERROR(IF(OR($N8="",$O8="",$P8=""),"",ROUND(ABS($P8-$N8)/ABS($N8-$O8),2)),"") | V8: =IFERROR(IF(OR($Q8="",$N8="",$S8=""),"",($Q8-$N8)*IF($G8="Buy",1,-1)*$S8*VLOOKUP($F8,'⚙️ Setelan'!$A$14:$F$20,4,FALSE)),"") | W8: =IFERROR(IF(OR($S8="",$F8=""),"",$S8*VLOOKUP($F8,'⚙️ Setelan'!$A$14:$F$20,5,FALSE)),"") | X8: =IF($V8="","",$V8-IF($W8="",0,$W8)) | Y8: =IF(OR($X8="",$T8="",$T8=0),"",ROUND($X8/$T8,2)) | Z8: =IF($X8="","",IF($X8>0,"Win",IF($X8<0,"Loss","BE"))) | AA8: =IF(OR($C8="",$D8=""),"",ROUND(MOD($D8-$C8,1)*1440,0)) | AD8: =IFERROR(IF(OR($AB8="",$T8="",$T8=0),"",ROUND(ABS($N8-$AB8)*$S8*VLOOKUP($F8,'⚙️ Setelan'!$A$14:$F$20,4,FALSE)/$T8,2)),"") | AE8: =IFERROR(IF(OR($AC8="",$T8="",$T8=0),"",ROUND(ABS($AC8-$N8)*$S8*VLOOKUP($F8,'⚙️ Setelan'!$A$14:$F$20,4,FALSE)/$T8,2)),"") | AK8: tiket 2313313925 · impor CSV · ⚠️ TANPA SL di broker — isi SL yang kamu niatkan biar Risiko $ dan R Hasil bisa terhitung | AL8: =IF(OR($C8="",$B8=""),"",IF(AND($Z7="Loss",$B8=$B7,MOD($C8-$D7,1)*1440<'⚙️ Setelan'!$B$9),"⚠️ Revenge","")) | AN8: =IF($AM8="","",IFERROR(IMAGE(IF(REGEXMATCH($AM8,"\.(png|jpg|jpeg|gif)$"),$AM8,"https://s3.tradingview.com/snapshots/"&LOWER(MID(REGEXEXTRACT($AM8,"/x/([A-Za-z0-9]+)"),1,1))&"/"&REGEXEXTRACT($AM8,"/x/([A-Za-z0-9]+)")&".png"),1),"⚠️ link tidak dikenali")) | AP8: =IF($AO8="","",IFERROR(IMAGE(IF(REGEXMATCH($AO8,"\.(png|jpg|jpeg|gif)$"),$AO8,"https://s3.tradingview.com/snapshots/"&LOWER(MID(REGEXEXTRACT($AO8,"/x/([A-Za-z0-9]+)"),1,1))&"/"&REGEXEXTRACT($AO8,"/x/([A-Za-z0-9]+)")&".png"),1),"⚠️ link tidak dikenali")) | AQ8: =IF($Z8="",0,IF(AND(OR('📊 Dashboard'!$B$4="(Semua)",$F8='📊 Dashboard'!$B$4),OR('📊 Dashboard'!$B$5="(Semua)",$H8='📊 Dashboard'!$B$5),OR('📊 Dashboard'!$B$6="(Semua)",$E8='📊 Dashboard'!$B$6),OR('📊 Dashboard'!$B$7="(Semua)",$AF8='📊 Dashboard'!$B$7),OR('📊 Dashboard'!$B$8="(Semua)",$AG8='📊 Dashboard'!$B$8),OR('📊 Dashboard'!$B$9="(Semua)",$K8='📊 Dashboard'!$B$9)),1,0))
A9: =IF($B9="","",ROW()-2) | B9: 46265 | C9: 0.37585648 | D9: 0.37658565 | E9: =IF($C9="","",IF(AND($C9>=TIME(14,0,0),$C9<TIME(19,30,0)),"London",IF(AND($C9>=TIME(19,30,0),$C9<TIME(23,0,0)),"Overlap LDN+NY",IF(OR($C9>=TIME(23,0,0),$C9<TIME(4,0,0)),"New York","Asia")))) | F9: XAUUSD | G9: Sell | N9: 4434.113 | Q9: 4430.431 | R9: =IFERROR(IF(OR($N9="",$O9="",$F9=""),"",ROUND(('⚙️ Setelan'!$B$3*'⚙️ Setelan'!$B$4/100)/(ABS($N9-$O9)*VLOOKUP($F9,'⚙️ Setelan'!$A$14:$F$20,4,FALSE)),2)),"") | S9: 0.09 | T9: =IFERROR(IF(OR($N9="",$O9="",$S9=""),"",ABS($N9-$O9)*$S9*VLOOKUP($F9,'⚙️ Setelan'!$A$14:$F$20,4,FALSE)),"") | U9: =IFERROR(IF(OR($N9="",$O9="",$P9=""),"",ROUND(ABS($P9-$N9)/ABS($N9-$O9),2)),"") | V9: =IFERROR(IF(OR($Q9="",$N9="",$S9=""),"",($Q9-$N9)*IF($G9="Buy",1,-1)*$S9*VLOOKUP($F9,'⚙️ Setelan'!$A$14:$F$20,4,FALSE)),"") | W9: =IFERROR(IF(OR($S9="",$F9=""),"",$S9*VLOOKUP($F9,'⚙️ Setelan'!$A$14:$F$20,5,FALSE)),"") | X9: =IF($V9="","",$V9-IF($W9="",0,$W9)) | Y9: =IF(OR($X9="",$T9="",$T9=0),"",ROUND($X9/$T9,2)) | Z9: =IF($X9="","",IF($X9>0,"Win",IF($X9<0,"Loss","BE"))) | AA9: =IF(OR($C9="",$D9=""),"",ROUND(MOD($D9-$C9,1)*1440,0)) | AD9: =IFERROR(IF(OR($AB9="",$T9="",$T9=0),"",ROUND(ABS($N9-$AB9)*$S9*VLOOKUP($F9,'⚙️ Setelan'!$A$14:$F$20,4,FALSE)/$T9,2)),"") | AE9: =IFERROR(IF(OR($AC9="",$T9="",$T9=0),"",ROUND(ABS($AC9-$N9)*$S9*VLOOKUP($F9,'⚙️ Setelan'!$A$14:$F$20,4,FALSE)/$T9,2)),"") | AK9: tiket 2313334563 · impor CSV · ⚠️ TANPA SL di broker — isi SL yang kamu niatkan biar Risiko $ dan R Hasil bisa terhitung | AL9: =IF(OR($C9="",$B9=""),"",IF(AND($Z8="Loss",$B9=$B8,MOD($C9-$D8,1)*1440<'⚙️ Setelan'!$B$9),"⚠️ Revenge","")) | AN9: =IF($AM9="","",IFERROR(IMAGE(IF(REGEXMATCH($AM9,"\.(png|jpg|jpeg|gif)$"),$AM9,"https://s3.tradingview.com/snapshots/"&LOWER(MID(REGEXEXTRACT($AM9,"/x/([A-Za-z0-9]+)"),1,1))&"/"&REGEXEXTRACT($AM9,"/x/([A-Za-z0-9]+)")&".png"),1),"⚠️ link tidak dikenali")) | AP9: =IF($AO9="","",IFERROR(IMAGE(IF(REGEXMATCH($AO9,"\.(png|jpg|jpeg|gif)$"),$AO9,"https://s3.tradingview.com/snapshots/"&LOWER(MID(REGEXEXTRACT($AO9,"/x/([A-Za-z0-9]+)"),1,1))&"/"&REGEXEXTRACT($AO9,"/x/([A-Za-z0-9]+)")&".png"),1),"⚠️ link tidak dikenali")) | AQ9: =IF($Z9="",0,IF(AND(OR('📊 Dashboard'!$B$4="(Semua)",$F9='📊 Dashboard'!$B$4),OR('📊 Dashboard'!$B$5="(Semua)",$H9='📊 Dashboard'!$B$5),OR('📊 Dashboard'!$B$6="(Semua)",$E9='📊 Dashboard'!$B$6),OR('📊 Dashboard'!$B$7="(Semua)",$AF9='📊 Dashboard'!$B$7),OR('📊 Dashboard'!$B$8="(Semua)",$AG9='📊 Dashboard'!$B$8),OR('📊 Dashboard'!$B$9="(Semua)",$K9='📊 Dashboard'!$B$9)),1,0))
A10: =IF($B10="","",ROW()-2) | B10: 46265 | C10: 0.37850694 | D10: 0.38121528 | E10: =IF($C10="","",IF(AND($C10>=TIME(14,0,0),$C10<TIME(19,30,0)),"London",IF(AND($C10>=TIME(19,30,0),$C10<TIME(23,0,0)),"Overlap LDN+NY",IF(OR($C10>=TIME(23,0,0),$C10<TIME(4,0,0)),"New York","Asia")))) | F10: XAUUSD | G10: Buy | N10: 4427.774 | O10: 4421.554 | P10: 4439.986 | Q10: 4432.601 | R10: =IFERROR(IF(OR($N10="",$O10="",$F10=""),"",ROUND(('⚙️ Setelan'!$B$3*'⚙️ Setelan'!$B$4/100)/(ABS($N10-$O10)*VLOOKUP($F10,'⚙️ Setelan'!$A$14:$F$20,4,FALSE)),2)),"") | S10: 0.09 | T10: =IFERROR(IF(OR($N10="",$O10="",$S10=""),"",ABS($N10-$O10)*$S10*VLOOKUP($F10,'⚙️ Setelan'!$A$14:$F$20,4,FALSE)),"") | U10: =IFERROR(IF(OR($N10="",$O10="",$P10=""),"",ROUND(ABS($P10-$N10)/ABS($N10-$O10),2)),"") | V10: =IFERROR(IF(OR($Q10="",$N10="",$S10=""),"",($Q10-$N10)*IF($G10="Buy",1,-1)*$S10*VLOOKUP($F10,'⚙️ Setelan'!$A$14:$F$20,4,FALSE)),"") | W10: =IFERROR(IF(OR($S10="",$F10=""),"",$S10*VLOOKUP($F10,'⚙️ Setelan'!$A$14:$F$20,5,FALSE)),"") | X10: =IF($V10="","",$V10-IF($W10="",0,$W10)) | Y10: =IF(OR($X10="",$T10="",$T10=0),"",ROUND($X10/$T10,2)) | Z10: =IF($X10="","",IF($X10>0,"Win",IF($X10<0,"Loss","BE"))) | AA10: =IF(OR($C10="",$D10=""),"",ROUND(MOD($D10-$C10,1)*1440,0)) | AD10: =IFERROR(IF(OR($AB10="",$T10="",$T10=0),"",ROUND(ABS($N10-$AB10)*$S10*VLOOKUP($F10,'⚙️ Setelan'!$A$14:$F$20,4,FALSE)/$T10,2)),"") | AE10: =IFERROR(IF(OR($AC10="",$T10="",$T10=0),"",ROUND(ABS($AC10-$N10)*$S10*VLOOKUP($F10,'⚙️ Setelan'!$A$14:$F$20,4,FALSE)/$T10,2)),"") | AK10: tiket 2313357536 · impor otomatis dari CSV broker | AL10: =IF(OR($C10="",$B10=""),"",IF(AND($Z9="Loss",$B10=$B9,MOD($C10-$D9,1)*1440<'⚙️ Setelan'!$B$9),"⚠️ Revenge","")) | AN10: =IF($AM10="","",IFERROR(IMAGE(IF(REGEXMATCH($AM10,"\.(png|jpg|jpeg|gif)$"),$AM10,"https://s3.tradingview.com/snapshots/"&LOWER(MID(REGEXEXTRACT($AM10,"/x/([A-Za-z0-9]+)"),1,1))&"/"&REGEXEXTRACT($AM10,"/x/([A-Za-z0-9]+)")&".png"),1),"⚠️ link tidak dikenali")) | AP10: =IF($AO10="","",IFERROR(IMAGE(IF(REGEXMATCH($AO10,"\.(png|jpg|jpeg|gif)$"),$AO10,"https://s3.tradingview.com/snapshots/"&LOWER(MID(REGEXEXTRACT($AO10,"/x/([A-Za-z0-9]+)"),1,1))&"/"&REGEXEXTRACT($AO10,"/x/([A-Za-z0-9]+)")&".png"),1),"⚠️ link tidak dikenali")) | AQ10: =IF($Z10="",0,IF(AND(OR('📊 Dashboard'!$B$4="(Semua)",$F10='📊 Dashboard'!$B$4),OR('📊 Dashboard'!$B$5="(Semua)",$H10='📊 Dashboard'!$B$5),OR('📊 Dashboard'!$B$6="(Semua)",$E10='📊 Dashboard'!$B$6),OR('📊 Dashboard'!$B$7="(Semua)",$AF10='📊 Dashboard'!$B$7),OR('📊 Dashboard'!$B$8="(Semua)",$AG10='📊 Dashboard'!$B$8),OR('📊 Dashboard'!$B$9="(Semua)",$K10='📊 Dashboard'!$B$9)),1,0))
A11: =IF($B11="","",ROW()-2) | B11: 46265 | C11: 0.37851852 | D11: 0.38121528 | E11: =IF($C11="","",IF(AND($C11>=TIME(14,0,0),$C11<TIME(19,30,0)),"London",IF(AND($C11>=TIME(19,30,0),$C11<TIME(23,0,0)),"Overlap LDN+NY",IF(OR($C11>=TIME(23,0,0),$C11<TIME(4,0,0)),"New York","Asia")))) | F11: XAUUSD | G11: Buy | N11: 4427.608 | O11: 4421.388 | P11: 4439.906 | Q11: 4432.601 | R11: =IFERROR(IF(OR($N11="",$O11="",$F11=""),"",ROUND(('⚙️ Setelan'!$B$3*'⚙️ Setelan'!$B$4/100)/(ABS($N11-$O11)*VLOOKUP($F11,'⚙️ Setelan'!$A$14:$F$20,4,FALSE)),2)),"") | S11: 0.09 | T11: =IFERROR(IF(OR($N11="",$O11="",$S11=""),"",ABS($N11-$O11)*$S11*VLOOKUP($F11,'⚙️ Setelan'!$A$14:$F$20,4,FALSE)),"") | U11: =IFERROR(IF(OR($N11="",$O11="",$P11=""),"",ROUND(ABS($P11-$N11)/ABS($N11-$O11),2)),"") | V11: =IFERROR(IF(OR($Q11="",$N11="",$S11=""),"",($Q11-$N11)*IF($G11="Buy",1,-1)*$S11*VLOOKUP($F11,'⚙️ Setelan'!$A$14:$F$20,4,FALSE)),"") | W11: =IFERROR(IF(OR($S11="",$F11=""),"",$S11*VLOOKUP($F11,'⚙️ Setelan'!$A$14:$F$20,5,FALSE)),"") | X11: =IF($V11="","",$V11-IF($W11="",0,$W11)) | Y11: =IF(OR($X11="",$T11="",$T11=0),"",ROUND($X11/$T11,2)) | Z11: =IF($X11="","",IF($X11>0,"Win",IF($X11<0,"Loss","BE"))) | AA11: =IF(OR($C11="",$D11=""),"",ROUND(MOD($D11-$C11,1)*1440,0)) | AD11: =IFERROR(IF(OR($AB11="",$T11="",$T11=0),"",ROUND(ABS($N11-$AB11)*$S11*VLOOKUP($F11,'⚙️ Setelan'!$A$14:$F$20,4,FALSE)/$T11,2)),"") | AE11: =IFERROR(IF(OR($AC11="",$T11="",$T11=0),"",ROUND(ABS($AC11-$N11)*$S11*VLOOKUP($F11,'⚙️ Setelan'!$A$14:$F$20,4,FALSE)/$T11,2)),"") | AK11: tiket 2313357553 · impor otomatis dari CSV broker | AL11: =IF(OR($C11="",$B11=""),"",IF(AND($Z10="Loss",$B11=$B10,MOD($C11-$D10,1)*1440<'⚙️ Setelan'!$B$9),"⚠️ Revenge","")) | AN11: =IF($AM11="","",IFERROR(IMAGE(IF(REGEXMATCH($AM11,"\.(png|jpg|jpeg|gif)$"),$AM11,"https://s3.tradingview.com/snapshots/"&LOWER(MID(REGEXEXTRACT($AM11,"/x/([A-Za-z0-9]+)"),1,1))&"/"&REGEXEXTRACT($AM11,"/x/([A-Za-z0-9]+)")&".png"),1),"⚠️ link tidak dikenali")) | AP11: =IF($AO11="","",IFERROR(IMAGE(IF(REGEXMATCH($AO11,"\.(png|jpg|jpeg|gif)$"),$AO11,"https://s3.tradingview.com/snapshots/"&LOWER(MID(REGEXEXTRACT($AO11,"/x/([A-Za-z0-9]+)"),1,1))&"/"&REGEXEXTRACT($AO11,"/x/([A-Za-z0-9]+)")&".png"),1),"⚠️ link tidak dikenali")) | AQ11: =IF($Z11="",0,IF(AND(OR('📊 Dashboard'!$B$4="(Semua)",$F11='📊 Dashboard'!$B$4),OR('📊 Dashboard'!$B$5="(Semua)",$H11='📊 Dashboard'!$B$5),OR('📊 Dashboard'!$B$6="(Semua)",$E11='📊 Dashboard'!$B$6),OR('📊 Dashboard'!$B$7="(Semua)",$AF11='📊 Dashboard'!$B$7),OR('📊 Dashboard'!$B$8="(Semua)",$AG11='📊 Dashboard'!$B$8),OR('📊 Dashboard'!$B$9="(Semua)",$K11='📊 Dashboard'!$B$9)),1,0))
A12: =IF($B12="","",ROW()-2) | E12: =IF($C12="","",IF(AND($C12>=TIME(14,0,0),$C12<TIME(19,30,0)),"London",IF(AND($C12>=TIME(19,30,0),$C12<TIME(23,0,0)),"Overlap LDN+NY",IF(OR($C12>=TIME(23,0,0),$C12<TIME(4,0,0)),"New York","Asia")))) | R12: =IFERROR(IF(OR($N12="",$O12="",$F12=""),"",ROUND(('⚙️ Setelan'!$B$3*'⚙️ Setelan'!$B$4/100)/(ABS($N12-$O12)*VLOOKUP($F12,'⚙️ Setelan'!$A$14:$F$20,4,FALSE)),2)),"") | T12: =IFERROR(IF(OR($N12="",$O12="",$S12=""),"",ABS($N12-$O12)*$S12*VLOOKUP($F12,'⚙️ Setelan'!$A$14:$F$20,4,FALSE)),"") | U12: =IFERROR(IF(OR($N12="",$O12="",$P12=""),"",ROUND(ABS($P12-$N12)/ABS($N12-$O12),2)),"") | V12: =IFERROR(IF(OR($Q12="",$N12="",$S12=""),"",($Q12-$N12)*IF($G12="Buy",1,-1)*$S12*VLOOKUP($F12,'⚙️ Setelan'!$A$14:$F$20,4,FALSE)),"") | W12: =IFERROR(IF(OR($S12="",$F12=""),"",$S12*VLOOKUP($F12,'⚙️ Setelan'!$A$14:$F$20,5,FALSE)),"") | X12: =IF($V12="","",$V12-IF($W12="",0,$W12)) | Y12: =IF(OR($X12="",$T12="",$T12=0),"",ROUND($X12/$T12,2)) | Z12: =IF($X12="","",IF($X12>0,"Win",IF($X12<0,"Loss","BE"))) | AA12: =IF(OR($C12="",$D12=""),"",ROUND(MOD($D12-$C12,1)*1440,0)) | AD12: =IFERROR(IF(OR($AB12="",$T12="",$T12=0),"",ROUND(ABS($N12-$AB12)*$S12*VLOOKUP($F12,'⚙️ Setelan'!$A$14:$F$20,4,FALSE)/$T12,2)),"") | AE12: =IFERROR(IF(OR($AC12="",$T12="",$T12=0),"",ROUND(ABS($AC12-$N12)*$S12*VLOOKUP($F12,'⚙️ Setelan'!$A$14:$F$20,4,FALSE)/$T12,2)),"") | AL12: =IF(OR($C12="",$B12=""),"",IF(AND($Z11="Loss",$B12=$B11,MOD($C12-$D11,1)*1440<'⚙️ Setelan'!$B$9),"⚠️ Revenge","")) | AN12: =IF($AM12="","",IFERROR(IMAGE(IF(REGEXMATCH($AM12,"\.(png|jpg|jpeg|gif)$"),$AM12,"https://s3.tradingview.com/snapshots/"&LOWER(MID(REGEXEXTRACT($AM12,"/x/([A-Za-z0-9]+)"),1,1))&"/"&REGEXEXTRACT($AM12,"/x/([A-Za-z0-9]+)")&".png"),1),"⚠️ link tidak dikenali")) | AP12: =IF($AO12="","",IFERROR(IMAGE(IF(REGEXMATCH($AO12,"\.(png|jpg|jpeg|gif)$"),$AO12,"https://s3.tradingview.com/snapshots/"&LOWER(MID(REGEXEXTRACT($AO12,"/x/([A-Za-z0-9]+)"),1,1))&"/"&REGEXEXTRACT($AO12,"/x/([A-Za-z0-9]+)")&".png"),1),"⚠️ link tidak dikenali")) | AQ12: =IF($Z12="",0,IF(AND(OR('📊 Dashboard'!$B$4="(Semua)",$F12='📊 Dashboard'!$B$4),OR('📊 Dashboard'!$B$5="(Semua)",$H12='📊 Dashboard'!$B$5),OR('📊 Dashboard'!$B$6="(Semua)",$E12='📊 Dashboard'!$B$6),OR('📊 Dashboard'!$B$7="(Semua)",$AF12='📊 Dashboard'!$B$7),OR('📊 Dashboard'!$B$8="(Semua)",$AG12='📊 Dashboard'!$B$8),OR('📊 Dashboard'!$B$9="(Semua)",$K12='📊 Dashboard'!$B$9)),1,0))
A13: =IF($B13="","",ROW()-2) | E13: =IF($C13="","",IF(AND($C13>=TIME(14,0,0),$C13<TIME(19,30,0)),"London",IF(AND($C13>=TIME(19,30,0),$C13<TIME(23,0,0)),"Overlap LDN+NY",IF(OR($C13>=TIME(23,0,0),$C13<TIME(4,0,0)),"New York","Asia")))) | R13: =IFERROR(IF(OR($N13="",$O13="",$F13=""),"",ROUND(('⚙️ Setelan'!$B$3*'⚙️ Setelan'!$B$4/100)/(ABS($N13-$O13)*VLOOKUP($F13,'⚙️ Setelan'!$A$14:$F$20,4,FALSE)),2)),"") | T13: =IFERROR(IF(OR($N13="",$O13="",$S13=""),"",ABS($N13-$O13)*$S13*VLOOKUP($F13,'⚙️ Setelan'!$A$14:$F$20,4,FALSE)),"") | U13: =IFERROR(IF(OR($N13="",$O13="",$P13=""),"",ROUND(ABS($P13-$N13)/ABS($N13-$O13),2)),"") | V13: =IFERROR(IF(OR($Q13="",$N13="",$S13=""),"",($Q13-$N13)*IF($G13="Buy",1,-1)*$S13*VLOOKUP($F13,'⚙️ Setelan'!$A$14:$F$20,4,FALSE)),"") | W13: =IFERROR(IF(OR($S13="",$F13=""),"",$S13*VLOOKUP($F13,'⚙️ Setelan'!$A$14:$F$20,5,FALSE)),"") | X13: =IF($V13="","",$V13-IF($W13="",0,$W13)) | Y13: =IF(OR($X13="",$T13="",$T13=0),"",ROUND($X13/$T13,2)) | Z13: =IF($X13="","",IF($X13>0,"Win",IF($X13<0,"Loss","BE"))) | AA13: =IF(OR($C13="",$D13=""),"",ROUND(MOD($D13-$C13,1)*1440,0)) | AD13: =IFERROR(IF(OR($AB13="",$T13="",$T13=0),"",ROUND(ABS($N13-$AB13)*$S13*VLOOKUP($F13,'⚙️ Setelan'!$A$14:$F$20,4,FALSE)/$T13,2)),"") | AE13: =IFERROR(IF(OR($AC13="",$T13="",$T13=0),"",ROUND(ABS($AC13-$N13)*$S13*VLOOKUP($F13,'⚙️ Setelan'!$A$14:$F$20,4,FALSE)/$T13,2)),"") | AL13: =IF(OR($C13="",$B13=""),"",IF(AND($Z12="Loss",$B13=$B12,MOD($C13-$D12,1)*1440<'⚙️ Setelan'!$B$9),"⚠️ Revenge","")) | AN13: =IF($AM13="","",IFERROR(IMAGE(IF(REGEXMATCH($AM13,"\.(png|jpg|jpeg|gif)$"),$AM13,"https://s3.tradingview.com/snapshots/"&LOWER(MID(REGEXEXTRACT($AM13,"/x/([A-Za-z0-9]+)"),1,1))&"/"&REGEXEXTRACT($AM13,"/x/([A-Za-z0-9]+)")&".png"),1),"⚠️ link tidak dikenali")) | AP13: =IF($AO13="","",IFERROR(IMAGE(IF(REGEXMATCH($AO13,"\.(png|jpg|jpeg|gif)$"),$AO13,"https://s3.tradingview.com/snapshots/"&LOWER(MID(REGEXEXTRACT($AO13,"/x/([A-Za-z0-9]+)"),1,1))&"/"&REGEXEXTRACT($AO13,"/x/([A-Za-z0-9]+)")&".png"),1),"⚠️ link tidak dikenali")) | AQ13: =IF($Z13="",0,IF(AND(OR('📊 Dashboard'!$B$4="(Semua)",$F13='📊 Dashboard'!$B$4),OR('📊 Dashboard'!$B$5="(Semua)",$H13='📊 Dashboard'!$B$5),OR('📊 Dashboard'!$B$6="(Semua)",$E13='📊 Dashboard'!$B$6),OR('📊 Dashboard'!$B$7="(Semua)",$AF13='📊 Dashboard'!$B$7),OR('📊 Dashboard'!$B$8="(Semua)",$AG13='📊 Dashboard'!$B$8),OR('📊 Dashboard'!$B$9="(Semua)",$K13='📊 Dashboard'!$B$9)),1,0))
A14: =IF($B14="","",ROW()-2) | E14: =IF($C14="","",IF(AND($C14>=TIME(14,0,0),$C14<TIME(19,30,0)),"London",IF(AND($C14>=TIME(19,30,0),$C14<TIME(23,0,0)),"Overlap LDN+NY",IF(OR($C14>=TIME(23,0,0),$C14<TIME(4,0,0)),"New York","Asia")))) | R14: =IFERROR(IF(OR($N14="",$O14="",$F14=""),"",ROUND(('⚙️ Setelan'!$B$3*'⚙️ Setelan'!$B$4/100)/(ABS($N14-$O14)*VLOOKUP($F14,'⚙️ Setelan'!$A$14:$F$20,4,FALSE)),2)),"") | T14: =IFERROR(IF(OR($N14="",$O14="",$S14=""),"",ABS($N14-$O14)*$S14*VLOOKUP($F14,'⚙️ Setelan'!$A$14:$F$20,4,FALSE)),"") | U14: =IFERROR(IF(OR($N14="",$O14="",$P14=""),"",ROUND(ABS($P14-$N14)/ABS($N14-$O14),2)),"") | V14: =IFERROR(IF(OR($Q14="",$N14="",$S14=""),"",($Q14-$N14)*IF($G14="Buy",1,-1)*$S14*VLOOKUP($F14,'⚙️ Setelan'!$A$14:$F$20,4,FALSE)),"") | W14: =IFERROR(IF(OR($S14="",$F14=""),"",$S14*VLOOKUP($F14,'⚙️ Setelan'!$A$14:$F$20,5,FALSE)),"") | X14: =IF($V14="","",$V14-IF($W14="",0,$W14)) | Y14: =IF(OR($X14="",$T14="",$T14=0),"",ROUND($X14/$T14,2)) | Z14: =IF($X14="","",IF($X14>0,"Win",IF($X14<0,"Loss","BE"))) | AA14: =IF(OR($C14="",$D14=""),"",ROUND(MOD($D14-$C14,1)*1440,0)) | AD14: =IFERROR(IF(OR($AB14="",$T14="",$T14=0),"",ROUND(ABS($N14-$AB14)*$S14*VLOOKUP($F14,'⚙️ Setelan'!$A$14:$F$20,4,FALSE)/$T14,2)),"") | AE14: =IFERROR(IF(OR($AC14="",$T14="",$T14=0),"",ROUND(ABS($AC14-$N14)*$S14*VLOOKUP($F14,'⚙️ Setelan'!$A$14:$F$20,4,FALSE)/$T14,2)),"") | AL14: =IF(OR($C14="",$B14=""),"",IF(AND($Z13="Loss",$B14=$B13,MOD($C14-$D13,1)*1440<'⚙️ Setelan'!$B$9),"⚠️ Revenge","")) | AN14: =IF($AM14="","",IFERROR(IMAGE(IF(REGEXMATCH($AM14,"\.(png|jpg|jpeg|gif)$"),$AM14,"https://s3.tradingview.com/snapshots/"&LOWER(MID(REGEXEXTRACT($AM14,"/x/([A-Za-z0-9]+)"),1,1))&"/"&REGEXEXTRACT($AM14,"/x/([A-Za-z0-9]+)")&".png"),1),"⚠️ link tidak dikenali")) | AP14: =IF($AO14="","",IFERROR(IMAGE(IF(REGEXMATCH($AO14,"\.(png|jpg|jpeg|gif)$"),$AO14,"https://s3.tradingview.com/snapshots/"&LOWER(MID(REGEXEXTRACT($AO14,"/x/([A-Za-z0-9]+)"),1,1))&"/"&REGEXEXTRACT($AO14,"/x/([A-Za-z0-9]+)")&".png"),1),"⚠️ link tidak dikenali")) | AQ14: =IF($Z14="",0,IF(AND(OR('📊 Dashboard'!$B$4="(Semua)",$F14='📊 Dashboard'!$B$4),OR('📊 Dashboard'!$B$5="(Semua)",$H14='📊 Dashboard'!$B$5),OR('📊 Dashboard'!$B$6="(Semua)",$E14='📊 Dashboard'!$B$6),OR('📊 Dashboard'!$B$7="(Semua)",$AF14='📊 Dashboard'!$B$7),OR('📊 Dashboard'!$B$8="(Semua)",$AG14='📊 Dashboard'!$B$8),OR('📊 Dashboard'!$B$9="(Semua)",$K14='📊 Dashboard'!$B$9)),1,0))
A15: =IF($B15="","",ROW()-2) | E15: =IF($C15="","",IF(AND($C15>=TIME(14,0,0),$C15<TIME(19,30,0)),"London",IF(AND($C15>=TIME(19,30,0),$C15<TIME(23,0,0)),"Overlap LDN+NY",IF(OR($C15>=TIME(23,0,0),$C15<TIME(4,0,0)),"New York","Asia")))) | R15: =IFERROR(IF(OR($N15="",$O15="",$F15=""),"",ROUND(('⚙️ Setelan'!$B$3*'⚙️ Setelan'!$B$4/100)/(ABS($N15-$O15)*VLOOKUP($F15,'⚙️ Setelan'!$A$14:$F$20,4,FALSE)),2)),"") | T15: =IFERROR(IF(OR($N15="",$O15="",$S15=""),"",ABS($N15-$O15)*$S15*VLOOKUP($F15,'⚙️ Setelan'!$A$14:$F$20,4,FALSE)),"") | U15: =IFERROR(IF(OR($N15="",$O15="",$P15=""),"",ROUND(ABS($P15-$N15)/ABS($N15-$O15),2)),"") | V15: =IFERROR(IF(OR($Q15="",$N15="",$S15=""),"",($Q15-$N15)*IF($G15="Buy",1,-1)*$S15*VLOOKUP($F15,'⚙️ Setelan'!$A$14:$F$20,4,FALSE)),"") | W15: =IFERROR(IF(OR($S15="",$F15=""),"",$S15*VLOOKUP($F15,'⚙️ Setelan'!$A$14:$F$20,5,FALSE)),"") | X15: =IF($V15="","",$V15-IF($W15="",0,$W15)) | Y15: =IF(OR($X15="",$T15="",$T15=0),"",ROUND($X15/$T15,2)) | Z15: =IF($X15="","",IF($X15>0,"Win",IF($X15<0,"Loss","BE"))) | AA15: =IF(OR($C15="",$D15=""),"",ROUND(MOD($D15-$C15,1)*1440,0)) | AD15: =IFERROR(IF(OR($AB15="",$T15="",$T15=0),"",ROUND(ABS($N15-$AB15)*$S15*VLOOKUP($F15,'⚙️ Setelan'!$A$14:$F$20,4,FALSE)/$T15,2)),"") | AE15: =IFERROR(IF(OR($AC15="",$T15="",$T15=0),"",ROUND(ABS($AC15-$N15)*$S15*VLOOKUP($F15,'⚙️ Setelan'!$A$14:$F$20,4,FALSE)/$T15,2)),"") | AL15: =IF(OR($C15="",$B15=""),"",IF(AND($Z14="Loss",$B15=$B14,MOD($C15-$D14,1)*1440<'⚙️ Setelan'!$B$9),"⚠️ Revenge","")) | AN15: =IF($AM15="","",IFERROR(IMAGE(IF(REGEXMATCH($AM15,"\.(png|jpg|jpeg|gif)$"),$AM15,"https://s3.tradingview.com/snapshots/"&LOWER(MID(REGEXEXTRACT($AM15,"/x/([A-Za-z0-9]+)"),1,1))&"/"&REGEXEXTRACT($AM15,"/x/([A-Za-z0-9]+)")&".png"),1),"⚠️ link tidak dikenali")) | AP15: =IF($AO15="","",IFERROR(IMAGE(IF(REGEXMATCH($AO15,"\.(png|jpg|jpeg|gif)$"),$AO15,"https://s3.tradingview.com/snapshots/"&LOWER(MID(REGEXEXTRACT($AO15,"/x/([A-Za-z0-9]+)"),1,1))&"/"&REGEXEXTRACT($AO15,"/x/([A-Za-z0-9]+)")&".png"),1),"⚠️ link tidak dikenali")) | AQ15: =IF($Z15="",0,IF(AND(OR('📊 Dashboard'!$B$4="(Semua)",$F15='📊 Dashboard'!$B$4),OR('📊 Dashboard'!$B$5="(Semua)",$H15='📊 Dashboard'!$B$5),OR('📊 Dashboard'!$B$6="(Semua)",$E15='📊 Dashboard'!$B$6),OR('📊 Dashboard'!$B$7="(Semua)",$AF15='📊 Dashboard'!$B$7),OR('📊 Dashboard'!$B$8="(Semua)",$AG15='📊 Dashboard'!$B$8),OR('📊 Dashboard'!$B$9="(Semua)",$K15='📊 Dashboard'!$B$9)),1,0))
A16: =IF($B16="","",ROW()-2) | E16: =IF($C16="","",IF(AND($C16>=TIME(14,0,0),$C16<TIME(19,30,0)),"London",IF(AND($C16>=TIME(19,30,0),$C16<TIME(23,0,0)),"Overlap LDN+NY",IF(OR($C16>=TIME(23,0,0),$C16<TIME(4,0,0)),"New York","Asia")))) | R16: =IFERROR(IF(OR($N16="",$O16="",$F16=""),"",ROUND(('⚙️ Setelan'!$B$3*'⚙️ Setelan'!$B$4/100)/(ABS($N16-$O16)*VLOOKUP($F16,'⚙️ Setelan'!$A$14:$F$20,4,FALSE)),2)),"") | T16: =IFERROR(IF(OR($N16="",$O16="",$S16=""),"",ABS($N16-$O16)*$S16*VLOOKUP($F16,'⚙️ Setelan'!$A$14:$F$20,4,FALSE)),"") | U16: =IFERROR(IF(OR($N16="",$O16="",$P16=""),"",ROUND(ABS($P16-$N16)/ABS($N16-$O16),2)),"") | V16: =IFERROR(IF(OR($Q16="",$N16="",$S16=""),"",($Q16-$N16)*IF($G16="Buy",1,-1)*$S16*VLOOKUP($F16,'⚙️ Setelan'!$A$14:$F$20,4,FALSE)),"") | W16: =IFERROR(IF(OR($S16="",$F16=""),"",$S16*VLOOKUP($F16,'⚙️ Setelan'!$A$14:$F$20,5,FALSE)),"") | X16: =IF($V16="","",$V16-IF($W16="",0,$W16)) | Y16: =IF(OR($X16="",$T16="",$T16=0),"",ROUND($X16/$T16,2)) | Z16: =IF($X16="","",IF($X16>0,"Win",IF($X16<0,"Loss","BE"))) | AA16: =IF(OR($C16="",$D16=""),"",ROUND(MOD($D16-$C16,1)*1440,0)) | AD16: =IFERROR(IF(OR($AB16="",$T16="",$T16=0),"",ROUND(ABS($N16-$AB16)*$S16*VLOOKUP($F16,'⚙️ Setelan'!$A$14:$F$20,4,FALSE)/$T16,2)),"") | AE16: =IFERROR(IF(OR($AC16="",$T16="",$T16=0),"",ROUND(ABS($AC16-$N16)*$S16*VLOOKUP($F16,'⚙️ Setelan'!$A$14:$F$20,4,FALSE)/$T16,2)),"") | AL16: =IF(OR($C16="",$B16=""),"",IF(AND($Z15="Loss",$B16=$B15,MOD($C16-$D15,1)*1440<'⚙️ Setelan'!$B$9),"⚠️ Revenge","")) | AN16: =IF($AM16="","",IFERROR(IMAGE(IF(REGEXMATCH($AM16,"\.(png|jpg|jpeg|gif)$"),$AM16,"https://s3.tradingview.com/snapshots/"&LOWER(MID(REGEXEXTRACT($AM16,"/x/([A-Za-z0-9]+)"),1,1))&"/"&REGEXEXTRACT($AM16,"/x/([A-Za-z0-9]+)")&".png"),1),"⚠️ link tidak dikenali")) | AP16: =IF($AO16="","",IFERROR(IMAGE(IF(REGEXMATCH($AO16,"\.(png|jpg|jpeg|gif)$"),$AO16,"https://s3.tradingview.com/snapshots/"&LOWER(MID(REGEXEXTRACT($AO16,"/x/([A-Za-z0-9]+)"),1,1))&"/"&REGEXEXTRACT($AO16,"/x/([A-Za-z0-9]+)")&".png"),1),"⚠️ link tidak dikenali")) | AQ16: =IF($Z16="",0,IF(AND(OR('📊 Dashboard'!$B$4="(Semua)",$F16='📊 Dashboard'!$B$4),OR('📊 Dashboard'!$B$5="(Semua)",$H16='📊 Dashboard'!$B$5),OR('📊 Dashboard'!$B$6="(Semua)",$E16='📊 Dashboard'!$B$6),OR('📊 Dashboard'!$B$7="(Semua)",$AF16='📊 Dashboard'!$B$7),OR('📊 Dashboard'!$B$8="(Semua)",$AG16='📊 Dashboard'!$B$8),OR('📊 Dashboard'!$B$9="(Semua)",$K16='📊 Dashboard'!$B$9)),1,0))
A17: =IF($B17="","",ROW()-2) | E17: =IF($C17="","",IF(AND($C17>=TIME(14,0,0),$C17<TIME(19,30,0)),"London",IF(AND($C17>=TIME(19,30,0),$C17<TIME(23,0,0)),"Overlap LDN+NY",IF(OR($C17>=TIME(23,0,0),$C17<TIME(4,0,0)),"New York","Asia")))) | R17: =IFERROR(IF(OR($N17="",$O17="",$F17=""),"",ROUND(('⚙️ Setelan'!$B$3*'⚙️ Setelan'!$B$4/100)/(ABS($N17-$O17)*VLOOKUP($F17,'⚙️ Setelan'!$A$14:$F$20,4,FALSE)),2)),"") | T17: =IFERROR(IF(OR($N17="",$O17="",$S17=""),"",ABS($N17-$O17)*$S17*VLOOKUP($F17,'⚙️ Setelan'!$A$14:$F$20,4,FALSE)),"") | U17: =IFERROR(IF(OR($N17="",$O17="",$P17=""),"",ROUND(ABS($P17-$N17)/ABS($N17-$O17),2)),"") | V17: =IFERROR(IF(OR($Q17="",$N17="",$S17=""),"",($Q17-$N17)*IF($G17="Buy",1,-1)*$S17*VLOOKUP($F17,'⚙️ Setelan'!$A$14:$F$20,4,FALSE)),"") | W17: =IFERROR(IF(OR($S17="",$F17=""),"",$S17*VLOOKUP($F17,'⚙️ Setelan'!$A$14:$F$20,5,FALSE)),"") | X17: =IF($V17="","",$V17-IF($W17="",0,$W17)) | Y17: =IF(OR($X17="",$T17="",$T17=0),"",ROUND($X17/$T17,2)) | Z17: =IF($X17="","",IF($X17>0,"Win",IF($X17<0,"Loss","BE"))) | AA17: =IF(OR($C17="",$D17=""),"",ROUND(MOD($D17-$C17,1)*1440,0)) | AD17: =IFERROR(IF(OR($AB17="",$T17="",$T17=0),"",ROUND(ABS($N17-$AB17)*$S17*VLOOKUP($F17,'⚙️ Setelan'!$A$14:$F$20,4,FALSE)/$T17,2)),"") | AE17: =IFERROR(IF(OR($AC17="",$T17="",$T17=0),"",ROUND(ABS($AC17-$N17)*$S17*VLOOKUP($F17,'⚙️ Setelan'!$A$14:$F$20,4,FALSE)/$T17,2)),"") | AL17: =IF(OR($C17="",$B17=""),"",IF(AND($Z16="Loss",$B17=$B16,MOD($C17-$D16,1)*1440<'⚙️ Setelan'!$B$9),"⚠️ Revenge","")) | AN17: =IF($AM17="","",IFERROR(IMAGE(IF(REGEXMATCH($AM17,"\.(png|jpg|jpeg|gif)$"),$AM17,"https://s3.tradingview.com/snapshots/"&LOWER(MID(REGEXEXTRACT($AM17,"/x/([A-Za-z0-9]+)"),1,1))&"/"&REGEXEXTRACT($AM17,"/x/([A-Za-z0-9]+)")&".png"),1),"⚠️ link tidak dikenali")) | AP17: =IF($AO17="","",IFERROR(IMAGE(IF(REGEXMATCH($AO17,"\.(png|jpg|jpeg|gif)$"),$AO17,"https://s3.tradingview.com/snapshots/"&LOWER(MID(REGEXEXTRACT($AO17,"/x/([A-Za-z0-9]+)"),1,1))&"/"&REGEXEXTRACT($AO17,"/x/([A-Za-z0-9]+)")&".png"),1),"⚠️ link tidak dikenali")) | AQ17: =IF($Z17="",0,IF(AND(OR('📊 Dashboard'!$B$4="(Semua)",$F17='📊 Dashboard'!$B$4),OR('📊 Dashboard'!$B$5="(Semua)",$H17='📊 Dashboard'!$B$5),OR('📊 Dashboard'!$B$6="(Semua)",$E17='📊 Dashboard'!$B$6),OR('📊 Dashboard'!$B$7="(Semua)",$AF17='📊 Dashboard'!$B$7),OR('📊 Dashboard'!$B$8="(Semua)",$AG17='📊 Dashboard'!$B$8),OR('📊 Dashboard'!$B$9="(Semua)",$K17='📊 Dashboard'!$B$9)),1,0))
A18: =IF($B18="","",ROW()-2) | E18: =IF($C18="","",IF(AND($C18>=TIME(14,0,0),$C18<TIME(19,30,0)),"London",IF(AND($C18>=TIME(19,30,0),$C18<TIME(23,0,0)),"Overlap LDN+NY",IF(OR($C18>=TIME(23,0,0),$C18<TIME(4,0,0)),"New York","Asia")))) | R18: =IFERROR(IF(OR($N18="",$O18="",$F18=""),"",ROUND(('⚙️ Setelan'!$B$3*'⚙️ Setelan'!$B$4/100)/(ABS($N18-$O18)*VLOOKUP($F18,'⚙️ Setelan'!$A$14:$F$20,4,FALSE)),2)),"") | T18: =IFERROR(IF(OR($N18="",$O18="",$S18=""),"",ABS($N18-$O18)*$S18*VLOOKUP($F18,'⚙️ Setelan'!$A$14:$F$20,4,FALSE)),"") | U18: =IFERROR(IF(OR($N18="",$O18="",$P18=""),"",ROUND(ABS($P18-$N18)/ABS($N18-$O18),2)),"") | V18: =IFERROR(IF(OR($Q18="",$N18="",$S18=""),"",($Q18-$N18)*IF($G18="Buy",1,-1)*$S18*VLOOKUP($F18,'⚙️ Setelan'!$A$14:$F$20,4,FALSE)),"") | W18: =IFERROR(IF(OR($S18="",$F18=""),"",$S18*VLOOKUP($F18,'⚙️ Setelan'!$A$14:$F$20,5,FALSE)),"") | X18: =IF($V18="","",$V18-IF($W18="",0,$W18)) | Y18: =IF(OR($X18="",$T18="",$T18=0),"",ROUND($X18/$T18,2)) | Z18: =IF($X18="","",IF($X18>0,"Win",IF($X18<0,"Loss","BE"))) | AA18: =IF(OR($C18="",$D18=""),"",ROUND(MOD($D18-$C18,1)*1440,0)) | AD18: =IFERROR(IF(OR($AB18="",$T18="",$T18=0),"",ROUND(ABS($N18-$AB18)*$S18*VLOOKUP($F18,'⚙️ Setelan'!$A$14:$F$20,4,FALSE)/$T18,2)),"") | AE18: =IFERROR(IF(OR($AC18="",$T18="",$T18=0),"",ROUND(ABS($AC18-$N18)*$S18*VLOOKUP($F18,'⚙️ Setelan'!$A$14:$F$20,4,FALSE)/$T18,2)),"") | AL18: =IF(OR($C18="",$B18=""),"",IF(AND($Z17="Loss",$B18=$B17,MOD($C18-$D17,1)*1440<'⚙️ Setelan'!$B$9),"⚠️ Revenge","")) | AN18: =IF($AM18="","",IFERROR(IMAGE(IF(REGEXMATCH($AM18,"\.(png|jpg|jpeg|gif)$"),$AM18,"https://s3.tradingview.com/snapshots/"&LOWER(MID(REGEXEXTRACT($AM18,"/x/([A-Za-z0-9]+)"),1,1))&"/"&REGEXEXTRACT($AM18,"/x/([A-Za-z0-9]+)")&".png"),1),"⚠️ link tidak dikenali")) | AP18: =IF($AO18="","",IFERROR(IMAGE(IF(REGEXMATCH($AO18,"\.(png|jpg|jpeg|gif)$"),$AO18,"https://s3.tradingview.com/snapshots/"&LOWER(MID(REGEXEXTRACT($AO18,"/x/([A-Za-z0-9]+)"),1,1))&"/"&REGEXEXTRACT($AO18,"/x/([A-Za-z0-9]+)")&".png"),1),"⚠️ link tidak dikenali")) | AQ18: =IF($Z18="",0,IF(AND(OR('📊 Dashboard'!$B$4="(Semua)",$F18='📊 Dashboard'!$B$4),OR('📊 Dashboard'!$B$5="(Semua)",$H18='📊 Dashboard'!$B$5),OR('📊 Dashboard'!$B$6="(Semua)",$E18='📊 Dashboard'!$B$6),OR('📊 Dashboard'!$B$7="(Semua)",$AF18='📊 Dashboard'!$B$7),OR('📊 Dashboard'!$B$8="(Semua)",$AG18='📊 Dashboard'!$B$8),OR('📊 Dashboard'!$B$9="(Semua)",$K18='📊 Dashboard'!$B$9)),1,0))
A19: =IF($B19="","",ROW()-2) | E19: =IF($C19="","",IF(AND($C19>=TIME(14,0,0),$C19<TIME(19,30,0)),"London",IF(AND($C19>=TIME(19,30,0),$C19<TIME(23,0,0)),"Overlap LDN+NY",IF(OR($C19>=TIME(23,0,0),$C19<TIME(4,0,0)),"New York","Asia")))) | R19: =IFERROR(IF(OR($N19="",$O19="",$F19=""),"",ROUND(('⚙️ Setelan'!$B$3*'⚙️ Setelan'!$B$4/100)/(ABS($N19-$O19)*VLOOKUP($F19,'⚙️ Setelan'!$A$14:$F$20,4,FALSE)),2)),"") | T19: =IFERROR(IF(OR($N19="",$O19="",$S19=""),"",ABS($N19-$O19)*$S19*VLOOKUP($F19,'⚙️ Setelan'!$A$14:$F$20,4,FALSE)),"") | U19: =IFERROR(IF(OR($N19="",$O19="",$P19=""),"",ROUND(ABS($P19-$N19)/ABS($N19-$O19),2)),"") | V19: =IFERROR(IF(OR($Q19="",$N19="",$S19=""),"",($Q19-$N19)*IF($G19="Buy",1,-1)*$S19*VLOOKUP($F19,'⚙️ Setelan'!$A$14:$F$20,4,FALSE)),"") | W19: =IFERROR(IF(OR($S19="",$F19=""),"",$S19*VLOOKUP($F19,'⚙️ Setelan'!$A$14:$F$20,5,FALSE)),"") | X19: =IF($V19="","",$V19-IF($W19="",0,$W19)) | Y19: =IF(OR($X19="",$T19="",$T19=0),"",ROUND($X19/$T19,2)) | Z19: =IF($X19="","",IF($X19>0,"Win",IF($X19<0,"Loss","BE"))) | AA19: =IF(OR($C19="",$D19=""),"",ROUND(MOD($D19-$C19,1)*1440,0)) | AD19: =IFERROR(IF(OR($AB19="",$T19="",$T19=0),"",ROUND(ABS($N19-$AB19)*$S19*VLOOKUP($F19,'⚙️ Setelan'!$A$14:$F$20,4,FALSE)/$T19,2)),"") | AE19: =IFERROR(IF(OR($AC19="",$T19="",$T19=0),"",ROUND(ABS($AC19-$N19)*$S19*VLOOKUP($F19,'⚙️ Setelan'!$A$14:$F$20,4,FALSE)/$T19,2)),"") | AL19: =IF(OR($C19="",$B19=""),"",IF(AND($Z18="Loss",$B19=$B18,MOD($C19-$D18,1)*1440<'⚙️ Setelan'!$B$9),"⚠️ Revenge","")) | AN19: =IF($AM19="","",IFERROR(IMAGE(IF(REGEXMATCH($AM19,"\.(png|jpg|jpeg|gif)$"),$AM19,"https://s3.tradingview.com/snapshots/"&LOWER(MID(REGEXEXTRACT($AM19,"/x/([A-Za-z0-9]+)"),1,1))&"/"&REGEXEXTRACT($AM19,"/x/([A-Za-z0-9]+)")&".png"),1),"⚠️ link tidak dikenali")) | AP19: =IF($AO19="","",IFERROR(IMAGE(IF(REGEXMATCH($AO19,"\.(png|jpg|jpeg|gif)$"),$AO19,"https://s3.tradingview.com/snapshots/"&LOWER(MID(REGEXEXTRACT($AO19,"/x/([A-Za-z0-9]+)"),1,1))&"/"&REGEXEXTRACT($AO19,"/x/([A-Za-z0-9]+)")&".png"),1),"⚠️ link tidak dikenali")) | AQ19: =IF($Z19="",0,IF(AND(OR('📊 Dashboard'!$B$4="(Semua)",$F19='📊 Dashboard'!$B$4),OR('📊 Dashboard'!$B$5="(Semua)",$H19='📊 Dashboard'!$B$5),OR('📊 Dashboard'!$B$6="(Semua)",$E19='📊 Dashboard'!$B$6),OR('📊 Dashboard'!$B$7="(Semua)",$AF19='📊 Dashboard'!$B$7),OR('📊 Dashboard'!$B$8="(Semua)",$AG19='📊 Dashboard'!$B$8),OR('📊 Dashboard'!$B$9="(Semua)",$K19='📊 Dashboard'!$B$9)),1,0))
A20: =IF($B20="","",ROW()-2) | E20: =IF($C20="","",IF(AND($C20>=TIME(14,0,0),$C20<TIME(19,30,0)),"London",IF(AND($C20>=TIME(19,30,0),$C20<TIME(23,0,0)),"Overlap LDN+NY",IF(OR($C20>=TIME(23,0,0),$C20<TIME(4,0,0)),"New York","Asia")))) | R20: =IFERROR(IF(OR($N20="",$O20="",$F20=""),"",ROUND(('⚙️ Setelan'!$B$3*'⚙️ Setelan'!$B$4/100)/(ABS($N20-$O20)*VLOOKUP($F20,'⚙️ Setelan'!$A$14:$F$20,4,FALSE)),2)),"") | T20: =IFERROR(IF(OR($N20="",$O20="",$S20=""),"",ABS($N20-$O20)*$S20*VLOOKUP($F20,'⚙️ Setelan'!$A$14:$F$20,4,FALSE)),"") | U20: =IFERROR(IF(OR($N20="",$O20="",$P20=""),"",ROUND(ABS($P20-$N20)/ABS($N20-$O20),2)),"") | V20: =IFERROR(IF(OR($Q20="",$N20="",$S20=""),"",($Q20-$N20)*IF($G20="Buy",1,-1)*$S20*VLOOKUP($F20,'⚙️ Setelan'!$A$14:$F$20,4,FALSE)),"") | W20: =IFERROR(IF(OR($S20="",$F20=""),"",$S20*VLOOKUP($F20,'⚙️ Setelan'!$A$14:$F$20,5,FALSE)),"") | X20: =IF($V20="","",$V20-IF($W20="",0,$W20)) | Y20: =IF(OR($X20="",$T20="",$T20=0),"",ROUND($X20/$T20,2)) | Z20: =IF($X20="","",IF($X20>0,"Win",IF($X20<0,"Loss","BE"))) | AA20: =IF(OR($C20="",$D20=""),"",ROUND(MOD($D20-$C20,1)*1440,0)) | AD20: =IFERROR(IF(OR($AB20="",$T20="",$T20=0),"",ROUND(ABS($N20-$AB20)*$S20*VLOOKUP($F20,'⚙️ Setelan'!$A$14:$F$20,4,FALSE)/$T20,2)),"") | AE20: =IFERROR(IF(OR($AC20="",$T20="",$T20=0),"",ROUND(ABS($AC20-$N20)*$S20*VLOOKUP($F20,'⚙️ Setelan'!$A$14:$F$20,4,FALSE)/$T20,2)),"") | AL20: =IF(OR($C20="",$B20=""),"",IF(AND($Z19="Loss",$B20=$B19,MOD($C20-$D19,1)*1440<'⚙️ Setelan'!$B$9),"⚠️ Revenge","")) | AN20: =IF($AM20="","",IFERROR(IMAGE(IF(REGEXMATCH($AM20,"\.(png|jpg|jpeg|gif)$"),$AM20,"https://s3.tradingview.com/snapshots/"&LOWER(MID(REGEXEXTRACT($AM20,"/x/([A-Za-z0-9]+)"),1,1))&"/"&REGEXEXTRACT($AM20,"/x/([A-Za-z0-9]+)")&".png"),1),"⚠️ link tidak dikenali")) | AP20: =IF($AO20="","",IFERROR(IMAGE(IF(REGEXMATCH($AO20,"\.(png|jpg|jpeg|gif)$"),$AO20,"https://s3.tradingview.com/snapshots/"&LOWER(MID(REGEXEXTRACT($AO20,"/x/([A-Za-z0-9]+)"),1,1))&"/"&REGEXEXTRACT($AO20,"/x/([A-Za-z0-9]+)")&".png"),1),"⚠️ link tidak dikenali")) | AQ20: =IF($Z20="",0,IF(AND(OR('📊 Dashboard'!$B$4="(Semua)",$F20='📊 Dashboard'!$B$4),OR('📊 Dashboard'!$B$5="(Semua)",$H20='📊 Dashboard'!$B$5),OR('📊 Dashboard'!$B$6="(Semua)",$E20='📊 Dashboard'!$B$6),OR('📊 Dashboard'!$B$7="(Semua)",$AF20='📊 Dashboard'!$B$7),OR('📊 Dashboard'!$B$8="(Semua)",$AG20='📊 Dashboard'!$B$8),OR('📊 Dashboard'!$B$9="(Semua)",$K20='📊 Dashboard'!$B$9)),1,0))
A21: =IF($B21="","",ROW()-2) | E21: =IF($C21="","",IF(AND($C21>=TIME(14,0,0),$C21<TIME(19,30,0)),"London",IF(AND($C21>=TIME(19,30,0),$C21<TIME(23,0,0)),"Overlap LDN+NY",IF(OR($C21>=TIME(23,0,0),$C21<TIME(4,0,0)),"New York","Asia")))) | R21: =IFERROR(IF(OR($N21="",$O21="",$F21=""),"",ROUND(('⚙️ Setelan'!$B$3*'⚙️ Setelan'!$B$4/100)/(ABS($N21-$O21)*VLOOKUP($F21,'⚙️ Setelan'!$A$14:$F$20,4,FALSE)),2)),"") | T21: =IFERROR(IF(OR($N21="",$O21="",$S21=""),"",ABS($N21-$O21)*$S21*VLOOKUP($F21,'⚙️ Setelan'!$A$14:$F$20,4,FALSE)),"") | U21: =IFERROR(IF(OR($N21="",$O21="",$P21=""),"",ROUND(ABS($P21-$N21)/ABS($N21-$O21),2)),"") | V21: =IFERROR(IF(OR($Q21="",$N21="",$S21=""),"",($Q21-$N21)*IF($G21="Buy",1,-1)*$S21*VLOOKUP($F21,'⚙️ Setelan'!$A$14:$F$20,4,FALSE)),"") | W21: =IFERROR(IF(OR($S21="",$F21=""),"",$S21*VLOOKUP($F21,'⚙️ Setelan'!$A$14:$F$20,5,FALSE)),"") | X21: =IF($V21="","",$V21-IF($W21="",0,$W21)) | Y21: =IF(OR($X21="",$T21="",$T21=0),"",ROUND($X21/$T21,2)) | Z21: =IF($X21="","",IF($X21>0,"Win",IF($X21<0,"Loss","BE"))) | AA21: =IF(OR($C21="",$D21=""),"",ROUND(MOD($D21-$C21,1)*1440,0)) | AD21: =IFERROR(IF(OR($AB21="",$T21="",$T21=0),"",ROUND(ABS($N21-$AB21)*$S21*VLOOKUP($F21,'⚙️ Setelan'!$A$14:$F$20,4,FALSE)/$T21,2)),"") | AE21: =IFERROR(IF(OR($AC21="",$T21="",$T21=0),"",ROUND(ABS($AC21-$N21)*$S21*VLOOKUP($F21,'⚙️ Setelan'!$A$14:$F$20,4,FALSE)/$T21,2)),"") | AL21: =IF(OR($C21="",$B21=""),"",IF(AND($Z20="Loss",$B21=$B20,MOD($C21-$D20,1)*1440<'⚙️ Setelan'!$B$9),"⚠️ Revenge","")) | AN21: =IF($AM21="","",IFERROR(IMAGE(IF(REGEXMATCH($AM21,"\.(png|jpg|jpeg|gif)$"),$AM21,"https://s3.tradingview.com/snapshots/"&LOWER(MID(REGEXEXTRACT($AM21,"/x/([A-Za-z0-9]+)"),1,1))&"/"&REGEXEXTRACT($AM21,"/x/([A-Za-z0-9]+)")&".png"),1),"⚠️ link tidak dikenali")) | AP21: =IF($AO21="","",IFERROR(IMAGE(IF(REGEXMATCH($AO21,"\.(png|jpg|jpeg|gif)$"),$AO21,"https://s3.tradingview.com/snapshots/"&LOWER(MID(REGEXEXTRACT($AO21,"/x/([A-Za-z0-9]+)"),1,1))&"/"&REGEXEXTRACT($AO21,"/x/([A-Za-z0-9]+)")&".png"),1),"⚠️ link tidak dikenali")) | AQ21: =IF($Z21="",0,IF(AND(OR('📊 Dashboard'!$B$4="(Semua)",$F21='📊 Dashboard'!$B$4),OR('📊 Dashboard'!$B$5="(Semua)",$H21='📊 Dashboard'!$B$5),OR('📊 Dashboard'!$B$6="(Semua)",$E21='📊 Dashboard'!$B$6),OR('📊 Dashboard'!$B$7="(Semua)",$AF21='📊 Dashboard'!$B$7),OR('📊 Dashboard'!$B$8="(Semua)",$AG21='📊 Dashboard'!$B$8),OR('📊 Dashboard'!$B$9="(Semua)",$K21='📊 Dashboard'!$B$9)),1,0))
A22: =IF($B22="","",ROW()-2) | E22: =IF($C22="","",IF(AND($C22>=TIME(14,0,0),$C22<TIME(19,30,0)),"London",IF(AND($C22>=TIME(19,30,0),$C22<TIME(23,0,0)),"Overlap LDN+NY",IF(OR($C22>=TIME(23,0,0),$C22<TIME(4,0,0)),"New York","Asia")))) | R22: =IFERROR(IF(OR($N22="",$O22="",$F22=""),"",ROUND(('⚙️ Setelan'!$B$3*'⚙️ Setelan'!$B$4/100)/(ABS($N22-$O22)*VLOOKUP($F22,'⚙️ Setelan'!$A$14:$F$20,4,FALSE)),2)),"") | T22: =IFERROR(IF(OR($N22="",$O22="",$S22=""),"",ABS($N22-$O22)*$S22*VLOOKUP($F22,'⚙️ Setelan'!$A$14:$F$20,4,FALSE)),"") | U22: =IFERROR(IF(OR($N22="",$O22="",$P22=""),"",ROUND(ABS($P22-$N22)/ABS($N22-$O22),2)),"") | V22: =IFERROR(IF(OR($Q22="",$N22="",$S22=""),"",($Q22-$N22)*IF($G22="Buy",1,-1)*$S22*VLOOKUP($F22,'⚙️ Setelan'!$A$14:$F$20,4,FALSE)),"") | W22: =IFERROR(IF(OR($S22="",$F22=""),"",$S22*VLOOKUP($F22,'⚙️ Setelan'!$A$14:$F$20,5,FALSE)),"") | X22: =IF($V22="","",$V22-IF($W22="",0,$W22)) | Y22: =IF(OR($X22="",$T22="",$T22=0),"",ROUND($X22/$T22,2)) | Z22: =IF($X22="","",IF($X22>0,"Win",IF($X22<0,"Loss","BE"))) | AA22: =IF(OR($C22="",$D22=""),"",ROUND(MOD($D22-$C22,1)*1440,0)) | AD22: =IFERROR(IF(OR($AB22="",$T22="",$T22=0),"",ROUND(ABS($N22-$AB22)*$S22*VLOOKUP($F22,'⚙️ Setelan'!$A$14:$F$20,4,FALSE)/$T22,2)),"") | AE22: =IFERROR(IF(OR($AC22="",$T22="",$T22=0),"",ROUND(ABS($AC22-$N22)*$S22*VLOOKUP($F22,'⚙️ Setelan'!$A$14:$F$20,4,FALSE)/$T22,2)),"") | AL22: =IF(OR($C22="",$B22=""),"",IF(AND($Z21="Loss",$B22=$B21,MOD($C22-$D21,1)*1440<'⚙️ Setelan'!$B$9),"⚠️ Revenge","")) | AN22: =IF($AM22="","",IFERROR(IMAGE(IF(REGEXMATCH($AM22,"\.(png|jpg|jpeg|gif)$"),$AM22,"https://s3.tradingview.com/snapshots/"&LOWER(MID(REGEXEXTRACT($AM22,"/x/([A-Za-z0-9]+)"),1,1))&"/"&REGEXEXTRACT($AM22,"/x/([A-Za-z0-9]+)")&".png"),1),"⚠️ link tidak dikenali")) | AP22: =IF($AO22="","",IFERROR(IMAGE(IF(REGEXMATCH($AO22,"\.(png|jpg|jpeg|gif)$"),$AO22,"https://s3.tradingview.com/snapshots/"&LOWER(MID(REGEXEXTRACT($AO22,"/x/([A-Za-z0-9]+)"),1,1))&"/"&REGEXEXTRACT($AO22,"/x/([A-Za-z0-9]+)")&".png"),1),"⚠️ link tidak dikenali")) | AQ22: =IF($Z22="",0,IF(AND(OR('📊 Dashboard'!$B$4="(Semua)",$F22='📊 Dashboard'!$B$4),OR('📊 Dashboard'!$B$5="(Semua)",$H22='📊 Dashboard'!$B$5),OR('📊 Dashboard'!$B$6="(Semua)",$E22='📊 Dashboard'!$B$6),OR('📊 Dashboard'!$B$7="(Semua)",$AF22='📊 Dashboard'!$B$7),OR('📊 Dashboard'!$B$8="(Semua)",$AG22='📊 Dashboard'!$B$8),OR('📊 Dashboard'!$B$9="(Semua)",$K22='📊 Dashboard'!$B$9)),1,0))
A23: =IF($B23="","",ROW()-2) | E23: =IF($C23="","",IF(AND($C23>=TIME(14,0,0),$C23<TIME(19,30,0)),"London",IF(AND($C23>=TIME(19,30,0),$C23<TIME(23,0,0)),"Overlap LDN+NY",IF(OR($C23>=TIME(23,0,0),$C23<TIME(4,0,0)),"New York","Asia")))) | R23: =IFERROR(IF(OR($N23="",$O23="",$F23=""),"",ROUND(('⚙️ Setelan'!$B$3*'⚙️ Setelan'!$B$4/100)/(ABS($N23-$O23)*VLOOKUP($F23,'⚙️ Setelan'!$A$14:$F$20,4,FALSE)),2)),"") | T23: =IFERROR(IF(OR($N23="",$O23="",$S23=""),"",ABS($N23-$O23)*$S23*VLOOKUP($F23,'⚙️ Setelan'!$A$14:$F$20,4,FALSE)),"") | U23: =IFERROR(IF(OR($N23="",$O23="",$P23=""),"",ROUND(ABS($P23-$N23)/ABS($N23-$O23),2)),"") | V23: =IFERROR(IF(OR($Q23="",$N23="",$S23=""),"",($Q23-$N23)*IF($G23="Buy",1,-1)*$S23*VLOOKUP($F23,'⚙️ Setelan'!$A$14:$F$20,4,FALSE)),"") | W23: =IFERROR(IF(OR($S23="",$F23=""),"",$S23*VLOOKUP($F23,'⚙️ Setelan'!$A$14:$F$20,5,FALSE)),"") | X23: =IF($V23="","",$V23-IF($W23="",0,$W23)) | Y23: =IF(OR($X23="",$T23="",$T23=0),"",ROUND($X23/$T23,2)) | Z23: =IF($X23="","",IF($X23>0,"Win",IF($X23<0,"Loss","BE"))) | AA23: =IF(OR($C23="",$D23=""),"",ROUND(MOD($D23-$C23,1)*1440,0)) | AD23: =IFERROR(IF(OR($AB23="",$T23="",$T23=0),"",ROUND(ABS($N23-$AB23)*$S23*VLOOKUP($F23,'⚙️ Setelan'!$A$14:$F$20,4,FALSE)/$T23,2)),"") | AE23: =IFERROR(IF(OR($AC23="",$T23="",$T23=0),"",ROUND(ABS($AC23-$N23)*$S23*VLOOKUP($F23,'⚙️ Setelan'!$A$14:$F$20,4,FALSE)/$T23,2)),"") | AL23: =IF(OR($C23="",$B23=""),"",IF(AND($Z22="Loss",$B23=$B22,MOD($C23-$D22,1)*1440<'⚙️ Setelan'!$B$9),"⚠️ Revenge","")) | AN23: =IF($AM23="","",IFERROR(IMAGE(IF(REGEXMATCH($AM23,"\.(png|jpg|jpeg|gif)$"),$AM23,"https://s3.tradingview.com/snapshots/"&LOWER(MID(REGEXEXTRACT($AM23,"/x/([A-Za-z0-9]+)"),1,1))&"/"&REGEXEXTRACT($AM23,"/x/([A-Za-z0-9]+)")&".png"),1),"⚠️ link tidak dikenali")) | AP23: =IF($AO23="","",IFERROR(IMAGE(IF(REGEXMATCH($AO23,"\.(png|jpg|jpeg|gif)$"),$AO23,"https://s3.tradingview.com/snapshots/"&LOWER(MID(REGEXEXTRACT($AO23,"/x/([A-Za-z0-9]+)"),1,1))&"/"&REGEXEXTRACT($AO23,"/x/([A-Za-z0-9]+)")&".png"),1),"⚠️ link tidak dikenali")) | AQ23: =IF($Z23="",0,IF(AND(OR('📊 Dashboard'!$B$4="(Semua)",$F23='📊 Dashboard'!$B$4),OR('📊 Dashboard'!$B$5="(Semua)",$H23='📊 Dashboard'!$B$5),OR('📊 Dashboard'!$B$6="(Semua)",$E23='📊 Dashboard'!$B$6),OR('📊 Dashboard'!$B$7="(Semua)",$AF23='📊 Dashboard'!$B$7),OR('📊 Dashboard'!$B$8="(Semua)",$AG23='📊 Dashboard'!$B$8),OR('📊 Dashboard'!$B$9="(Semua)",$K23='📊 Dashboard'!$B$9)),1,0))
... A152: =IF($B152="","",ROW()-2) | E152: =IF($C152="","",IF(AND($C152>=TIME(14,0,0),$C152<TIME(19,30,0)),"London",IF(AND($C152>=TIME(19,30,0),$C152<TIME(23,0,0)),"Overlap LDN+NY",IF(OR($C152>=TIME(23,0,0),$C152<TIME(4,0,0)),"New York","Asia")))) | R152: =IFERROR(IF(OR($N152="",$O152="",$F152=""),"",ROUND(('⚙️ Setelan'!$B$3*'⚙️ Setelan'!$B$4/100)/(ABS($N152-$O152)*VLOOKUP($F152,'⚙️ Setelan'!$A$14:$F$20,4,FALSE)),2)),"") | T152: =IFERROR(IF(OR($N152="",$O152="",$S152=""),"",ABS($N152-$O152)*$S152*VLOOKUP($F152,'⚙️ Setelan'!$A$14:$F$20,4,FALSE)),"") | U152: =IFERROR(IF(OR($N152="",$O152="",$P152=""),"",ROUND(ABS($P152-$N152)/ABS($N152-$O152),2)),"") | V152: =IFERROR(IF(OR($Q152="",$N152="",$S152=""),"",($Q152-$N152)*IF($G152="Buy",1,-1)*$S152*VLOOKUP($F152,'⚙️ Setelan'!$A$14:$F$20,4,FALSE)),"") | W152: =IFERROR(IF(OR($S152="",$F152=""),"",$S152*VLOOKUP($F152,'⚙️ Setelan'!$A$14:$F$20,5,FALSE)),"") | X152: =IF($V152="","",$V152-IF($W152="",0,$W152)) | Y152: =IF(OR($X152="",$T152="",$T152=0),"",ROUND($X152/$T152,2)) | Z152: =IF($X152="","",IF($X152>0,"Win",IF($X152<0,"Loss","BE"))) | AA152: =IF(OR($C152="",$D152=""),"",ROUND(MOD($D152-$C152,1)*1440,0)) | AD152: =IFERROR(IF(OR($AB152="",$T152="",$T152=0),"",ROUND(ABS($N152-$AB152)*$S152*VLOOKUP($F152,'⚙️ Setelan'!$A$14:$F$20,4,FALSE)/$T152,2)),"") | AE152: =IFERROR(IF(OR($AC152="",$T152="",$T152=0),"",ROUND(ABS($AC152-$N152)*$S152*VLOOKUP($F152,'⚙️ Setelan'!$A$14:$F$20,4,FALSE)/$T152,2)),"") | AL152: =IF(OR($C152="",$B152=""),"",IF(AND($Z151="Loss",$B152=$B151,MOD($C152-$D151,1)*1440<'⚙️ Setelan'!$B$9),"⚠️ Revenge","")) | AN152: =IF($AM152="","",IFERROR(IMAGE(IF(REGEXMATCH($AM152,"\.(png|jpg|jpeg|gif)$"),$AM152,"https://s3.tradingview.com/snapshots/"&LOWER(MID(REGEXEXTRACT($AM152,"/x/([A-Za-z0-9]+)"),1,1))&"/"&REGEXEXTRACT($AM152,"/x/([A-Za-z0-9]+)")&".png"),1),"⚠️ link tidak dikenali")) | AP152: =IF($AO152="","",IFERROR(IMAGE(IF(REGEXMATCH($AO152,"\.(png|jpg|jpeg|gif)$"),$AO152,"https://s3.tradingview.com/snapshots/"&LOWER(MID(REGEXEXTRACT($AO152,"/x/([A-Za-z0-9]+)"),1,1))&"/"&REGEXEXTRACT($AO152,"/x/([A-Za-z0-9]+)")&".png"),1),"⚠️ link tidak dikenali")) | AQ152: =IF($Z152="",0,IF(AND(OR('📊 Dashboard'!$B$4="(Semua)",$F152='📊 Dashboard'!$B$4),OR('📊 Dashboard'!$B$5="(Semua)",$H152='📊 Dashboard'!$B$5),OR('📊 Dashboard'!$B$6="(Semua)",$E152='📊 Dashboard'!$B$6),OR('📊 Dashboard'!$B$7="(Semua)",$AF152='📊 Dashboard'!$B$7),OR('📊 Dashboard'!$B$8="(Semua)",$AG152='📊 Dashboard'!$B$8),OR('📊 Dashboard'!$B$9="(Semua)",$K152='📊 Dashboard'!$B$9)),1,0))

Sheet 📅 Harian
A1: 📅 REKAP HARIAN — August 2026
A2: Tanggal | B2: Trade | C2: PnL Bersih $ | D2: Total R | E2: Win Rate | F2: Status Guardrail | G2: Kumulatif R | H2: Puncak R | I2: Drawdown R
A3: 46235 | B3: =(COUNTIFS('📒 Jurnal'!$B$3:$B$152,$A3,'📒 Jurnal'!$Z$3:$Z$152,"Win")+COUNTIFS('📒 Jurnal'!$B$3:$B$152,$A3,'📒 Jurnal'!$Z$3:$Z$152,"Loss")+COUNTIFS('📒 Jurnal'!$B$3:$B$152,$A3,'📒 Jurnal'!$Z$3:$Z$152,"BE")) | C3: =SUMIFS('📒 Jurnal'!$X$3:$X$152,'📒 Jurnal'!$B$3:$B$152,$A3) | D3: =SUMIFS('📒 Jurnal'!$Y$3:$Y$152,'📒 Jurnal'!$B$3:$B$152,$A3) | E3: =IFERROR(COUNTIFS('📒 Jurnal'!$B$3:$B$152,$A3,'📒 Jurnal'!$Z$3:$Z$152,"Win")/(COUNTIFS('📒 Jurnal'!$B$3:$B$152,$A3,'📒 Jurnal'!$Z$3:$Z$152,"Win")+COUNTIFS('📒 Jurnal'!$B$3:$B$152,$A3,'📒 Jurnal'!$Z$3:$Z$152,"Loss")+COUNTIFS('📒 Jurnal'!$B$3:$B$152,$A3,'📒 Jurnal'!$Z$3:$Z$152,"BE")),"") | F3: =IF($B3=0,"—",IF(OR($C3<=-'⚙️ Setelan'!$B$5,$B3>'⚙️ Setelan'!$B$6,COUNTIFS('📒 Jurnal'!$B$3:$B$152,$A3,'📒 Jurnal'!$AL$3:$AL$152,"⚠️ Revenge")>0),"🔴 LANGGAR","✅ Aman")) | G3: =SUM($D$3:$D3) | H3: =MAX($G$3:$G3) | I3: =$H3-$G3
A4: 46236 | B4: =(COUNTIFS('📒 Jurnal'!$B$3:$B$152,$A4,'📒 Jurnal'!$Z$3:$Z$152,"Win")+COUNTIFS('📒 Jurnal'!$B$3:$B$152,$A4,'📒 Jurnal'!$Z$3:$Z$152,"Loss")+COUNTIFS('📒 Jurnal'!$B$3:$B$152,$A4,'📒 Jurnal'!$Z$3:$Z$152,"BE")) | C4: =SUMIFS('📒 Jurnal'!$X$3:$X$152,'📒 Jurnal'!$B$3:$B$152,$A4) | D4: =SUMIFS('📒 Jurnal'!$Y$3:$Y$152,'📒 Jurnal'!$B$3:$B$152,$A4) | E4: =IFERROR(COUNTIFS('📒 Jurnal'!$B$3:$B$152,$A4,'📒 Jurnal'!$Z$3:$Z$152,"Win")/(COUNTIFS('📒 Jurnal'!$B$3:$B$152,$A4,'📒 Jurnal'!$Z$3:$Z$152,"Win")+COUNTIFS('📒 Jurnal'!$B$3:$B$152,$A4,'📒 Jurnal'!$Z$3:$Z$152,"Loss")+COUNTIFS('📒 Jurnal'!$B$3:$B$152,$A4,'📒 Jurnal'!$Z$3:$Z$152,"BE")),"") | F4: =IF($B4=0,"—",IF(OR($C4<=-'⚙️ Setelan'!$B$5,$B4>'⚙️ Setelan'!$B$6,COUNTIFS('📒 Jurnal'!$B$3:$B$152,$A4,'📒 Jurnal'!$AL$3:$AL$152,"⚠️ Revenge")>0),"🔴 LANGGAR","✅ Aman")) | G4: =SUM($D$3:$D4) | H4: =MAX($G$3:$G4) | I4: =$H4-$G4
